Workbook

Sheet EDE_INF
I1: No modificar columna! | K1: No modificar columna!
A2: TCCN | B2: PTE | C2: ZZZ | D2: TTT | E2: UUU | F2: VVV | G2: WWW | H2: Ocultar | I2: MASCARA SAP | J2: DENOMINACIÓN | K2: NIVEL | L2: TAG N° | M2: TIPO UT
A4: TCCN | H4: =CONCATENATE(A4,"-",B4,"-",C4,"-",D4,"-",E4,"-",F4,"-",G4) -> TCCN------ | I4: =MID(H4,1,(LEN(H4)-VLOOKUP(K4,datos!$B$2:$C$12,2,0))) -> TCCN | J4: GERENCIA DE FUNDICION | K4: =VLOOKUP(LEN(SUBSTITUTE(H4,"-","")),datos!$A$1:$B$12,2,0) -> 1 | M4: P
A5: TCCN | B5: PTE | H5: =CONCATENATE(A5,"-",B5,"-",C5,"-",D5,"-",E5,"-",F5,"-",G5) -> TCCN-PTE----- | I5: =MID(H5,1,(LEN(H5)-VLOOKUP(K5,datos!$B$2:$C$12,2,0))) -> TCCN-PTE | J5: PLANTA TRATAMIENTO DE ESCORIA | K5: =VLOOKUP(LEN(SUBSTITUTE(H5,"-","")),datos!$A$1:$B$12,2,0) -> 2 | M5: P
A6: TCCN | B6: PTE | C6: PCH | H6: =CONCATENATE(A6,"-",B6,"-",C6,"-",D6,"-",E6,"-",F6,"-",G6) -> TCCN-PTE-PCH---- | I6: =MID(H6,1,(LEN(H6)-VLOOKUP(K6,datos!$B$2:$C$12,2,0))) -> TCCN-PTE-PCH | J6: 7100 - CHANCADO Y ACOPIO | K6: =VLOOKUP(LEN(SUBSTITUTE(H6,"-","")),datos!$A$1:$B$12,2,0) -> 3 | M6: P
A7: TCCN | B7: PTE | C7: PCH | D7: CNP | H7: =CONCATENATE(A7,"-",B7,"-",C7,"-",D7,"-",E7,"-",F7,"-",G7) -> TCCN-PTE-PCH-CNP--- | I7: =MID(H7,1,(LEN(H7)-VLOOKUP(K7,datos!$B$2:$C$12,2,0))) -> TCCN-PTE-PCH-CNP | J7: RECEPCION CHANCADO ACOPIO- 7110/20/80 | K7: =VLOOKUP(LEN(SUBSTITUTE(H7,"-","")),datos!$A$1:$B$12,2,0) -> 4 | M7: P
A8: TCCN | B8: PTE | C8: PCH | D8: CNP | E8: PTF | H8: =CONCATENATE(A8,"-",B8,"-",C8,"-",D8,"-",E8,"-",F8,"-",G8) -> TCCN-PTE-PCH-CNP-PTF-- | I8: =MID(H8,1,(LEN(H8)-VLOOKUP(K8,datos!$B$2:$C$12,2,0))) -> TCCN-PTE-PCH-CNP-PTF | J8: PLATAFORMA DE DESCARGA | K8: =VLOOKUP(LEN(SUBSTITUTE(H8,"-","")),datos!$A$1:$B$12,2,0) -> 5 | M8: P
A9: TCCN | B9: PTE | C9: PCH | D9: CNP | E9: PTF | F9: INS | H9: =CONCATENATE(A9,"-",B9,"-",C9,"-",D9,"-",E9,"-",F9,"-",G9) -> TCCN-PTE-PCH-CNP-PTF-INS- | I9: =MID(H9,1,(LEN(H9)-VLOOKUP(K9,datos!$B$2:$C$12,2,0))) -> TCCN-PTE-PCH-CNP-PTF-INS | J9: SISTEMA INSTRUMENTACION PLATAFORMA DESC | K9: =VLOOKUP(LEN(SUBSTITUTE(H9,"-","")),datos!$A$1:$B$12,2,0) -> 6 | M9: P
A10: TCCN | B10: PTE | C10: PCH | D10: CNP | E10: PTF | F10: INS | G10: SMF | H10: =CONCATENATE(A10,"-",B10,"-",C10,"-",D10,"-",E10,"-",F10,"-",G10) -> TCCN-PTE-PCH-CNP-PTF-INS-SMF | I10: =MID(H10,1,(LEN(H10)-VLOOKUP(K10,datos!$B$2:$C$12,2,0))) -> TCCN-PTE-PCH-CNP-PTF-INS-SMF | J10: SEMAFORO PLATAFORMA DESCARGA | K10: =VLOOKUP(LEN(SUBSTITUTE(H10,"-","")),datos!$A$1:$B$12,2,0) -> 7 | L10: 07110-YL-0100 | M10: P
A11: TCCN | B11: PTE | C11: PCH | D11: CNP | E11: PTF | F11: INS | G11: SPO | H11: =CONCATENATE(A11,"-",B11,"-",C11,"-",D11,"-",E11,"-",F11,"-",G11) -> TCCN-PTE-PCH-CNP-PTF-INS-SPO | I11: =MID(H11,1,(LEN(H11)-VLOOKUP(K11,datos!$B$2:$C$12,2,0))) -> TCCN-PTE-PCH-CNP-PTF-INS-SPO | J11: POSICION CAMION PLATAFORMA DESCARGA | K11: =VLOOKUP(LEN(SUBSTITUTE(H11,"-","")),datos!$A$1:$B$12,2,0) -> 7 | L11: 07110-ZS/ZX-0103 | M11: P
A12: TCCN | B12: PTE | C12: PCH | D12: CNP | E12: TOL | H12: =CONCATENATE(A12,"-",B12,"-",C12,"-",D12,"-",E12,"-",F12,"-",G12) -> TCCN-PTE-PCH-CNP-TOL-- | I12: =MID(H12,1,(LEN(H12)-VLOOKUP(K12,datos!$B$2:$C$12,2,0))) -> TCCN-PTE-PCH-CNP-TOL | J12: TOLVA RECEPCION DE ESCORIA | K12: =VLOOKUP(LEN(SUBSTITUTE(H12,"-","")),datos!$A$1:$B$12,2,0) -> 5 | L12: 07110-TOL-001 | M12: P
A13: TCCN | B13: PTE | C13: PCH | D13: CNP | E13: TOL | F13: INS | H13: =CONCATENATE(A13,"-",B13,"-",C13,"-",D13,"-",E13,"-",F13,"-",G13) -> TCCN-PTE-PCH-CNP-TOL-INS- | I13: =MID(H13,1,(LEN(H13)-VLOOKUP(K13,datos!$B$2:$C$12,2,0))) -> TCCN-PTE-PCH-CNP-TOL-INS | J13: SISTEMA INSTRUMENTACION TOLVA RECEPCION | K13: =VLOOKUP(LEN(SUBSTITUTE(H13,"-","")),datos!$A$1:$B$12,2,0) -> 6 | M13: P
A14: TCCN | B14: PTE | C14: PCH | D14: CNP | E14: TOL | F14: INS | G14: MNV | H14: =CONCATENATE(A14,"-",B14,"-",C14,"-",D14,"-",E14,"-",F14,"-",G14) -> TCCN-PTE-PCH-CNP-TOL-INS-MNV | I14: =MID(H14,1,(LEN(H14)-VLOOKUP(K14,datos!$B$2:$C$12,2,0))) -> TCCN-PTE-PCH-CNP-TOL-INS-MNV | J14: NIVEL TOLVA 7110-TOL-001 | K14: =VLOOKUP(LEN(SUBSTITUTE(H14,"-","")),datos!$A$1:$B$12,2,0) -> 7 | L14: 07110-LE/LIT-0105 | M14: P
A15: TCCN | B15: PTE | C15: PCH | D15: CNP | E15: SLZ | H15: =CONCATENATE(A15,"-",B15,"-",C15,"-",D15,"-",E15,"-",F15,"-",G15) -> TCCN-PTE-PCH-CNP-SLZ-- | I15: =MID(H15,1,(LEN(H15)-VLOOKUP(K15,datos!$B$2:$C$12,2,0))) -> TCCN-PTE-PCH-CNP-SLZ | J15: SISTEMA LANZAS TOLVA RECEPCION | K15: =VLOOKUP(LEN(SUBSTITUTE(H15,"-","")),datos!$A$1:$B$12,2,0) -> 5 | L15: 07110-SLZ-001 | M15: P
A16: TCCN | B16: PTE | C16: PCH | D16: CNP | E16: SLZ | F16: SHI | H16: =CONCATENATE(A16,"-",B16,"-",C16,"-",D16,"-",E16,"-",F16,"-",G16) -> TCCN-PTE-PCH-CNP-SLZ-SHI- | I16: =MID(H16,1,(LEN(H16)-VLOOKUP(K16,datos!$B$2:$C$12,2,0))) -> TCCN-PTE-PCH-CNP-SLZ-SHI | J16: SISTEMA HIDRAULICO SLZ. 7110-SLZ-001 | K16: =VLOOKUP(LEN(SUBSTITUTE(H16,"-","")),datos!$A$1:$B$12,2,0) -> 6 | L16: 07110-SLZ-001-01 | M16: P
A17: TCCN | B17: PTE | C17: PCH | D17: CNP | E17: SLZ | F17: SHI | G17: CIH | H17: =CONCATENATE(A17,"-",B17,"-",C17,"-",D17,"-",E17,"-",F17,"-",G17) -> TCCN-PTE-PCH-CNP-SLZ-SHI-CIH | I17: =MID(H17,1,(LEN(H17)-VLOOKUP(K17,datos!$B$2:$C$12,2,0))) -> TCCN-PTE-PCH-CNP-SLZ-SHI-CIH | J17: CILINDROS ACTUADORES SLZ. 7110-SLZ-001 | K17: =VLOOKUP(LEN(SUBSTITUTE(H17,"-","")),datos!$A$1:$B$12,2,0) -> 7 | M17: P
A18: TCCN | B18: PTE | C18: PCH | D18: CNP | E18: SLZ | F18: SHI | G18: BBA | H18: =CONCATENATE(A18,"-",B18,"-",C18,"-",D18,"-",E18,"-",F18,"-",G18) -> TCCN-PTE-PCH-CNP-SLZ-SHI-BBA | I18: =MID(H18,1,(LEN(H18)-VLOOKUP(K18,datos!$B$2:$C$12,2,0))) -> TCCN-PTE-PCH-CNP-SLZ-SHI-BBA | J18: BOMBA UHD SLZ. 7110-SLZ-001 | K18: =VLOOKUP(LEN(SUBSTITUTE(H18,"-","")),datos!$A$1:$B$12,2,0) -> 7 | M18: P
A19: TCCN | B19: PTE | C19: PCH | D19: CNP | E19: SLZ | F19: SHI | G19: EST | H19: =CONCATENATE(A19,"-",B19,"-",C19,"-",D19,"-",E19,"-",F19,"-",G19) -> TCCN-PTE-PCH-CNP-SLZ-SHI-EST | I19: =MID(H19,1,(LEN(H19)-VLOOKUP(K19,datos!$B$2:$C$12,2,0))) -> TCCN-PTE-PCH-CNP-SLZ-SHI-EST | J19: ESTANQUE UHD SLZ. 7110-SLZ-001 | K19: =VLOOKUP(LEN(SUBSTITUTE(H19,"-","")),datos!$A$1:$B$12,2,0) -> 7 | M19: P
A20: TCCN | B20: PTE | C20: PCH | D20: CNP | E20: SLZ | F20: SHI | G20: MOE | H20: =CONCATENATE(A20,"-",B20,"-",C20,"-",D20,"-",E20,"-",F20,"-",G20) -> TCCN-PTE-PCH-CNP-SLZ-SHI-MOE | I20: =MID(H20,1,(LEN(H20)-VLOOKUP(K20,datos!$B$2:$C$12,2,0))) -> TCCN-PTE-PCH-CNP-SLZ-SHI-MOE | J20: MOTOR ELEC UHD SLZ. 7110-SLZ-001 | K20: =VLOOKUP(LEN(SUBSTITUTE(H20,"-","")),datos!$A$1:$B$12,2,0) -> 7 | L20: 07110-SLZ-001-01M | M20: P
A21: TCCN | B21: PTE | C21: PCH | D21: CNP | E21: SLZ | F21: SHI | G21: CUH | H21: =CONCATENATE(A21,"-",B21,"-",C21,"-",D21,"-",E21,"-",F21,"-",G21) -> TCCN-PTE-PCH-CNP-SLZ-SHI-CUH | I21: =MID(H21,1,(LEN(H21)-VLOOKUP(K21,datos!$B$2:$C$12,2,0))) -> TCCN-PTE-PCH-CNP-SLZ-SHI-CUH | J21: CALEFACTOR ESTANQUE UHD SLZ 7110-SLZ-001 | K21: =VLOOKUP(LEN(SUBSTITUTE(H21,"-","")),datos!$A$1:$B$12,2,0) -> 7 | L21: 07110-SLZ-001-01-1 | M21: P
A22: TCCN | B22: PTE | C22: PCH | D22: CNP | E22: SLZ | F22: SME | H22: =CONCATENATE(A22,"-",B22,"-",C22,"-",D22,"-",E22,"-",F22,"-",G22) -> TCCN-PTE-PCH-CNP-SLZ-SME- | I22: =MID(H22,1,(LEN(H22)-VLOOKUP(K22,datos!$B$2:$C$12,2,0))) -> TCCN-PTE-PCH-CNP-SLZ-SME | J22: SISTEMA MECANICO SLZ. 7110-SLZ-001 | K22: =VLOOKUP(LEN(SUBSTITUTE(H22,"-","")),datos!$A$1:$B$12,2,0) -> 6 | M22: P
A23: TCCN | B23: PTE | C23: PCH | D23: CNP | E23: SLZ | F23: SME | G23: LAN | H23: =CONCATENATE(A23,"-",B23,"-",C23,"-",D23,"-",E23,"-",F23,"-",G23) -> TCCN-PTE-PCH-CNP-SLZ-SME-LAN | I23: =MID(H23,1,(LEN(H23)-VLOOKUP(K23,datos!$B$2:$C$12,2,0))) -> TCCN-PTE-PCH-CNP-SLZ-SME-LAN | J23: SET DE LANZAS SLZ. 7110-SLZ-001 | K23: =VLOOKUP(LEN(SUBSTITUTE(H23,"-","")),datos!$A$1:$B$12,2,0) -> 7 | M23: P
A24: TCCN | B24: PTE | C24: PCH | D24: CNP | E24: SLZ | F24: SME | G24: CRL | H24: =CONCATENATE(A24,"-",B24,"-",C24,"-",D24,"-",E24,"-",F24,"-",G24) -> TCCN-PTE-PCH-CNP-SLZ-SME-CRL | I24: =MID(H24,1,(LEN(H24)-VLOOKUP(K24,datos!$B$2:$C$12,2,0))) -> TCCN-PTE-PCH-CNP-SLZ-SME-CRL | J24: CARRO LANZAS SLZ 7110-SLZ-001 | K24: =VLOOKUP(LEN(SUBSTITUTE(H24,"-","")),datos!$A$1:$B$12,2,0) -> 7 | M24: P
A25: TCCN | B25: PTE | C25: PCH | D25: CNP | E25: SLZ | F25: SES | H25: =CONCATENATE(A25,"-",B25,"-",C25,"-",D25,"-",E25,"-",F25,"-",G25) -> TCCN-PTE-PCH-CNP-SLZ-SES- | I25: =MID(H25,1,(LEN(H25)-VLOOKUP(K25,datos!$B$2:$C$12,2,0))) -> TCCN-PTE-PCH-CNP-SLZ-SES | J25: SISTEMA ESTRUCTURAL SLZ. 7110-SLZ-001 | K25: =VLOOKUP(LEN(SUBSTITUTE(H25,"-","")),datos!$A$1:$B$12,2,0) -> 6 | M25: P
A26: TCCN | B26: PTE | C26: PCH | D26: CNP | E26: SLZ | F26: SES | G26: CHU | H26: =CONCATENATE(A26,"-",B26,"-",C26,"-",D26,"-",E26,"-",F26,"-",G26) -> TCCN-PTE-PCH-CNP-SLZ-SES-CHU | I26: =MID(H26,1,(LEN(H26)-VLOOKUP(K26,datos!$B$2:$C$12,2,0))) -> TCCN-PTE-PCH-CNP-SLZ-SES-CHU | J26: CHUTE SLZ. 7110-SLZ-001 | K26: =VLOOKUP(LEN(SUBSTITUTE(H26,"-","")),datos!$A$1:$B$12,2,0) -> 7 | L26: 07110-SLZ-001-02 | M26: P
A27: TCCN | B27: PTE | C27: PCH | D27: CNP | E27: SD1 | H27: =CONCATENATE(A27,"-",B27,"-",C27,"-",D27,"-",E27,"-",F27,"-",G27) -> TCCN-PTE-PCH-CNP-SD1-- | I27: =MID(H27,1,(LEN(H27)-VLOOKUP(K27,datos!$B$2:$C$12,2,0))) -> TCCN-PTE-PCH-CNP-SD1 | J27: SUPRESOR DE POLVO DESCARGA CAMIONES | K27: =VLOOKUP(LEN(SUBSTITUTE(H27,"-","")),datos!$A$1:$B$12,2,0) -> 5 | L27: 07110-SDP-001 | M27: P
A28: TCCN | B28: PTE | C28: PCH | D28: CNP | E28: SD1 | F28: SHN | H28: =CONCATENATE(A28,"-",B28,"-",C28,"-",D28,"-",E28,"-",F28,"-",G28) -> TCCN-PTE-PCH-CNP-SD1-SHN- | I28: =MID(H28,1,(LEN(H28)-VLOOKUP(K28,datos!$B$2:$C$12,2,0))) -> TCCN-PTE-PCH-CNP-SD1-SHN | J28: SISTEMA HIDRONEUMATICO SDP. 7110-SDP-001 | K28: =VLOOKUP(LEN(SUBSTITUTE(H28,"-","")),datos!$A$1:$B$12,2,0) -> 6 | M28: P
A29: TCCN | B29: PTE | C29: PCH | D29: CNP | E29: SD1 | F29: SHN | G29: BVV | H29: =CONCATENATE(A29,"-",B29,"-",C29,"-",D29,"-",E29,"-",F29,"-",G29) -> TCCN-PTE-PCH-CNP-SD1-SHN-BVV | I29: =MID(H29,1,(LEN(H29)-VLOOKUP(K29,datos!$B$2:$C$12,2,0))) -> TCCN-PTE-PCH-CNP-SD1-SHN-BVV | J29: BANCO VVAS. SDP. 7120-SDP-001 | K29: =VLOOKUP(LEN(SUBSTITUTE(H29,"-","")),datos!$A$1:$B$12,2,0) -> 7 | M29: P
A30: TCCN | B30: PTE | C30: PCH | D30: CNP | E30: SD1 | F30: INS | H30: =CONCATENATE(A30,"-",B30,"-",C30,"-",D30,"-",E30,"-",F30,"-",G30) -> TCCN-PTE-PCH-CNP-SD1-INS- | I30: =MID(H30,1,(LEN(H30)-VLOOKUP(K30,datos!$B$2:$C$12,2,0))) -> TCCN-PTE-PCH-CNP-SD1-INS | J30: SISTEMA INSTRUMENTACION SDP 7120-SDP-001 | K30: =VLOOKUP(LEN(SUBSTITUTE(H30,"-","")),datos!$A$1:$B$12,2,0) -> 6 | M30: P
A31: TCCN | B31: PTE | C31: PCH | D31: CNP | E31: SD1 | F31: INS | G31: GMO | H31: =CONCATENATE(A31,"-",B31,"-",C31,"-",D31,"-",E31,"-",F31,"-",G31) -> TCCN-PTE-PCH-CNP-SD1-INS-GMO | I31: =MID(H31,1,(LEN(H31)-VLOOKUP(K31,datos!$B$2:$C$12,2,0))) -> TCCN-PTE-PCH-CNP-SD1-INS-GMO | J31: GABINETE CTRL. Y MONITOREO 7120-SDP-001 | K31: =VLOOKUP(LEN(SUBSTITUTE(H31,"-","")),datos!$A$1:$B$12,2,0) -> 7 | M31: P
A32: TCCN | B32: PTE | C32: PCH | D32: CNP | E32: SD1 | F32: INS | G32: FJM | H32: =CONCATENATE(A32,"-",B32,"-",C32,"-",D32,"-",E32,"-",F32,"-",G32) -> TCCN-PTE-PCH-CNP-SD1-INS-FJM | I32: =MID(H32,1,(LEN(H32)-VLOOKUP(K32,datos!$B$2:$C$12,2,0))) -> TCCN-PTE-PCH-CNP-SD1-INS-FJM | J32: FLUJOMETRO SUPRESOR POLVO 7110-SDP-001 | K32: =VLOOKUP(LEN(SUBSTITUTE(H32,"-","")),datos!$A$1:$B$12,2,0) -> 7 | L32: 07110-FE/FT-2202 | M32: P
A33: TCCN | B33: PTE | C33: PCH | D33: CNP | E33: APC | H33: =CONCATENATE(A33,"-",B33,"-",C33,"-",D33,"-",E33,"-",F33,"-",G33) -> TCCN-PTE-PCH-CNP-APC-- | I33: =MID(H33,1,(LEN(H33)-VLOOKUP(K33,datos!$B$2:$C$12,2,0))) -> TCCN-PTE-PCH-CNP-APC | J33: ALIMENTADOR DE PLACAS TOLVA ESCORIA | K33: =VLOOKUP(LEN(SUBSTITUTE(H33,"-","")),datos!$A$1:$B$12,2,0) -> 5 | L33: 07120-APC-001 | M33: P
A34: TCCN | B34: PTE | C34: PCH | D34: CNP | E34: APC | F34: SME | H34: =CONCATENATE(A34,"-",B34,"-",C34,"-",D34,"-",E34,"-",F34,"-",G34) -> TCCN-PTE-PCH-CNP-APC-SME- | I34: =MID(H34,1,(LEN(H34)-VLOOKUP(K34,datos!$B$2:$C$12,2,0))) -> TCCN-PTE-PCH-CNP-APC-SME | J34: SISTEMA MECANICO APC. 7120-APC-001 | K34: =VLOOKUP(LEN(SUBSTITUTE(H34,"-","")),datos!$A$1:$B$12,2,0) -> 6 | M34: P
A35: TCCN | B35: PTE | C35: PCH | D35: CNP | E35: APC | F35: SME | G35: RUE | H35: =CONCATENATE(A35,"-",B35,"-",C35,"-",D35,"-",E35,"-",F35,"-",G35) -> TCCN-PTE-PCH-CNP-APC-SME-RUE | I35: =MID(H35,1,(LEN(H35)-VLOOKUP(K35,datos!$B$2:$C$12,2,0))) -> TCCN-PTE-PCH-CNP-APC-SME-RUE | J35: RUEDA COLA APC. 7120-APC-001 | K35: =VLOOKUP(LEN(SUBSTITUTE(H35,"-","")),datos!$A$1:$B$12,2,0) -> 7 | M35: P
A36: TCCN | B36: PTE | C36: PCH | D36: CNP | E36: APC | F36: SME | G36: PNN | H36: =CONCATENATE(A36,"-",B36,"-",C36,"-",D36,"-",E36,"-",F36,"-",G36) -> TCCN-PTE-PCH-CNP-APC-SME-PNN | I36: =MID(H36,1,(LEN(H36)-VLOOKUP(K36,datos!$B$2:$C$12,2,0))) -> TCCN-PTE-PCH-CNP-APC-SME-PNN | J36: PIÑON CABEZA APC. 7120-APC-001 | K36: =VLOOKUP(LEN(SUBSTITUTE(H36,"-","")),datos!$A$1:$B$12,2,0) -> 7 | M36: P
A37: TCCN | B37: PTE | C37: PCH | D37: CNP | E37: APC | F37: SME | G37: CZP | H37: =CONCATENATE(A37,"-",B37,"-",C37,"-",D37,"-",E37,"-",F37,"-",G37) -> TCCN-PTE-PCH-CNP-APC-SME-CZP | I37: =MID(H37,1,(LEN(H37)-VLOOKUP(K37,datos!$B$2:$C$12,2,0))) -> TCCN-PTE-PCH-CNP-APC-SME-CZP | J37: CADENA APC. 7120-APC-001 | K37: =VLOOKUP(LEN(SUBSTITUTE(H37,"-","")),datos!$A$1:$B$12,2,0) -> 7 | M37: P
A38: TCCN | B38: PTE | C38: PCH | D38: CNP | E38: APC | F38: SME | G38: PLA | H38: =CONCATENATE(A38,"-",B38,"-",C38,"-",D38,"-",E38,"-",F38,"-",G38) -> TCCN-PTE-PCH-CNP-APC-SME-PLA | I38: =MID(H38,1,(LEN(H38)-VLOOKUP(K38,datos!$B$2:$C$12,2,0))) -> TCCN-PTE-PCH-CNP-APC-SME-PLA | J38: PLACAS APC. 7120-APC-001 | K38: =VLOOKUP(LEN(SUBSTITUTE(H38,"-","")),datos!$A$1:$B$12,2,0) -> 7 | M38: P
A39: TCCN | B39: PTE | C39: PCH | D39: CNP | E39: APC | F39: INS | H39: =CONCATENATE(A39,"-",B39,"-",C39,"-",D39,"-",E39,"-",F39,"-",G39) -> TCCN-PTE-PCH-CNP-APC-INS- | I39: =MID(H39,1,(LEN(H39)-VLOOKUP(K39,datos!$B$2:$C$12,2,0))) -> TCCN-PTE-PCH-CNP-APC-INS | J39: SISTEMA INSTRUMENTACION APC 7120-APC-001 | K39: =VLOOKUP(LEN(SUBSTITUTE(H39,"-","")),datos!$A$1:$B$12,2,0) -> 6 | M39: P
A40: TCCN | B40: PTE | C40: PCH | D40: CNP | E40: APC | F40: INS | G40: PE1 | H40: =CONCATENATE(A40,"-",B40,"-",C40,"-",D40,"-",E40,"-",F40,"-",G40) -> TCCN-PTE-PCH-CNP-APC-INS-PE1 | I40: =MID(H40,1,(LEN(H40)-VLOOKUP(K40,datos!$B$2:$C$12,2,0))) -> TCCN-PTE-PCH-CNP-APC-INS-PE1 | J40: PARADA DE EMERGENCIA APC. 7120-APC-001 | K40: =VLOOKUP(LEN(SUBSTITUTE(H40,"-","")),datos!$A$1:$B$12,2,0) -> 7 | L40: 07120-HSS-0113A@B | M40: P
A41: TCCN | B41: PTE | C41: PCH | D41: CNP | E41: APC | F41: INS | G41: SAM | H41: =CONCATENATE(A41,"-",B41,"-",C41,"-",D41,"-",E41,"-",F41,"-",G41) -> TCCN-PTE-PCH-CNP-APC-INS-SAM | I41: =MID(H41,1,(LEN(H41)-VLOOKUP(K41,datos!$B$2:$C$12,2,0))) -> TCCN-PTE-PCH-CNP-APC-INS-SAM | J41: SENSOR DE ATOLLO APC. 7120-APC-001 | K41: =VLOOKUP(LEN(SUBSTITUTE(H41,"-","")),datos!$A$1:$B$12,2,0) -> 7 | L41: 07120-LE/LX-108 | M41: P
...

Sheet ECO_EDE
A1: División (1 Nivel) | C1: Planta (2 Nivel) | E1: Proceso (3 Nivel) | G1: Agrupación (4 Nivel) | I1: Equipo Unitario (5 Nivel) | L1: SISTEMA (6 Nivel) | N1: Componente | P1: Equipo Principal
A2: U.T. División | B2: Descripción División | C2: U.T. Planta | D2: Descripción Planta | E2: U.T. Proceso | F2: Descripción Proceso | G2: U.T. Agrupación | H2: Descripción Agrupación | I2: U.T. Equipo | J2: Descripción Equipo | K2: Descripción Técnica | L2: U.T. Sistema | M2: Descripción Sistema | N2: U.T. Componente | O2: Descripción Componente
A3: TCCN | B3: EL TENIENTE GERENCIA DE PLANTAS | C3: TCCN-PTE | D3: PLANTA TRATAMIENTO DE ESCORIA | E3: TCCN-PTE-PCH | F3: 7100 - CHANCADO Y ACOPIO | G3: TCCN-PTE-PCH-CNP | H3: CHANCADO PRIMARIO | I3: TCCN-PTE-PCH-CNP-TOL | J3: TOLVA RECEPCION DE ESCORIA N°1
A4: TCCN | B4: EL TENIENTE GERENCIA DE PLANTAS | C4: TCCN-PTE | D4: PLANTA TRATAMIENTO DE ESCORIA | E4: TCCN-PTE-PCH | F4: 7100 - CHANCADO Y ACOPIO | G4: TCCN-PTE-PCH-CNP | H4: CHANCADO PRIMARIO | I4: TCCN-PTE-PCH-CNP-SLZ | J4: SISTEMA LANZAS TOLVA RECEPCION | L4: TCCN-PTE-PCH-CNP-SLZ-SHI | M4: UNIDAD HIDRAULICA | N4: TCCN-PTE-PCH-CNP-SLZ-SHI-CIH | O4: CILINDROS ACTUADORES LANZAS TOLVA RECEP.
A5: TCCN | B5: EL TENIENTE GERENCIA DE PLANTAS | C5: TCCN-PTE | D5: PLANTA TRATAMIENTO DE ESCORIA | E5: TCCN-PTE-PCH | F5: 7100 - CHANCADO Y ACOPIO | G5: TCCN-PTE-PCH-CNP | H5: CHANCADO PRIMARIO | I5: TCCN-PTE-PCH-CNP-SLZ | J5: SISTEMA LANZAS TOLVA RECEPCION | L5: TCCN-PTE-PCH-CNP-SLZ-SHI | M5: UNIDAD HIDRAULICA | N5: TCCN-PTE-PCH-CNP-SLZ-SHI-BBA | O5: BOMBA HIDR LANZAS TOLVA RECEP.
A6: TCCN | B6: EL TENIENTE GERENCIA DE PLANTAS | C6: TCCN-PTE | D6: PLANTA TRATAMIENTO DE ESCORIA | E6: TCCN-PTE-PCH | F6: 7100 - CHANCADO Y ACOPIO | G6: TCCN-PTE-PCH-CNP | H6: CHANCADO PRIMARIO | I6: TCCN-PTE-PCH-CNP-SLZ | J6: SISTEMA LANZAS TOLVA RECEPCION | L6: TCCN-PTE-PCH-CNP-SLZ-SHI | M6: UNIDAD HIDRAULICA | N6: TCCN-PTE-PCH-CNP-SLZ-SHI-ETQ | O6: ESTANQUE LANZAS TOLVA RECEP.
A7: TCCN | B7: EL TENIENTE GERENCIA DE PLANTAS | C7: TCCN-PTE | D7: PLANTA TRATAMIENTO DE ESCORIA | E7: TCCN-PTE-PCH | F7: 7100 - CHANCADO Y ACOPIO | G7: TCCN-PTE-PCH-CNP | H7: CHANCADO PRIMARIO | I7: TCCN-PTE-PCH-CNP-SLZ | J7: SISTEMA LANZAS TOLVA RECEPCION | L7: TCCN-PTE-PCH-CNP-SLZ-SHI | M7: UNIDAD HIDRAULICA | N7: TCCN-PTE-PCH-CNP-SLZ-SHI-MOE | O7: MOTOR ELEC LANZAS TOLVA RECEP.
A8: TCCN | B8: EL TENIENTE GERENCIA DE PLANTAS | C8: TCCN-PTE | D8: PLANTA TRATAMIENTO DE ESCORIA | E8: TCCN-PTE-PCH | F8: 7100 - CHANCADO Y ACOPIO | G8: TCCN-PTE-PCH-CNP | H8: CHANCADO PRIMARIO | I8: TCCN-PTE-PCH-CNP-SLZ | J8: SISTEMA LANZAS TOLVA RECEPCION | L8: TCCN-PTE-PCH-CNP-SLZ-SHI | M8: UNIDAD HIDRAULICA | N8: TCCN-PTE-PCH-CNP-SLZ-SHI-CUH | O8: CALEFACTOR EN DEPOSITO
A9: TCCN | B9: EL TENIENTE GERENCIA DE PLANTAS | C9: TCCN-PTE | D9: PLANTA TRATAMIENTO DE ESCORIA | E9: TCCN-PTE-PCH | F9: 7100 - CHANCADO Y ACOPIO | G9: TCCN-PTE-PCH-CNP | H9: CHANCADO PRIMARIO | I9: TCCN-PTE-PCH-CNP-SLZ | J9: SISTEMA LANZAS TOLVA RECEPCION | L9: TCCN-PTE-PCH-CNP-SLZ-SME | M9: SISTEMA MECANICO | N9: TCCN-PTE-PCH-CNP-SLZ-SME-LAN | O9: SET DE LANZAS
A10: TCCN | B10: EL TENIENTE GERENCIA DE PLANTAS | C10: TCCN-PTE | D10: PLANTA TRATAMIENTO DE ESCORIA | E10: TCCN-PTE-PCH | F10: 7100 - CHANCADO Y ACOPIO | G10: TCCN-PTE-PCH-CNP | H10: CHANCADO PRIMARIO | I10: TCCN-PTE-PCH-CNP-SLZ | J10: SISTEMA LANZAS TOLVA RECEPCION | L10: TCCN-PTE-PCH-CNP-SLZ-SME | M10: SISTEMA MECANICO | N10: TCCN-PTE-PCH-CNP-SLZ-SME-CRL | O10: CARRO LANZAS
A11: TCCN | B11: EL TENIENTE GERENCIA DE PLANTAS | C11: TCCN-PTE | D11: PLANTA TRATAMIENTO DE ESCORIA | E11: TCCN-PTE-PCH | F11: 7100 - CHANCADO Y ACOPIO | G11: TCCN-PTE-PCH-CNP | H11: CHANCADO PRIMARIO | I11: TCCN-PTE-PCH-CNP-SLZ | J11: SISTEMA LANZAS TOLVA RECEPCION | L11: TCCN-PTE-PCH-CNP-SLZ-SES | M11: SISTEMA ESTRUCTURAL | N11: TCCN-PTE-PCH-CNP-SLZ-SES-CHU | O11: CHUTE SISTEMA DE LANZAS
A12: TCCN | B12: EL TENIENTE GERENCIA DE PLANTAS | C12: TCCN-PTE | D12: PLANTA TRATAMIENTO DE ESCORIA | E12: TCCN-PTE-PCH | F12: 7100 - CHANCADO Y ACOPIO | G12: TCCN-PTE-PCH-CNP | H12: CHANCADO PRIMARIO | I12: TCCN-PTE-PCH-CNP-APC | J12: ALIMENTADOR DE PLACAS TOLVA ESCORIA N°1 | L12: TCCN-PTE-PCH-CNP-APC-SME | M12: SISTEMA MECANICO | N12: TCCN-PTE-PCH-CNP-APC-SME-RUE | O12: RUEDA DE COLA ALIMENTADOR PLACAS TOLVA 1
A13: TCCN | B13: EL TENIENTE GERENCIA DE PLANTAS | C13: TCCN-PTE | D13: PLANTA TRATAMIENTO DE ESCORIA | E13: TCCN-PTE-PCH | F13: 7100 - CHANCADO Y ACOPIO | G13: TCCN-PTE-PCH-CNP | H13: CHANCADO PRIMARIO | I13: TCCN-PTE-PCH-CNP-APC | J13: ALIMENTADOR DE PLACAS TOLVA ESCORIA N°1 | L13: TCCN-PTE-PCH-CNP-APC-SME | M13: SISTEMA MECANICO | N13: TCCN-PTE-PCH-CNP-APC-SME-PNN | O13: PIÑON DE CABEZA ALIMENTAD PLACAS TOLVA 1
A14: TCCN | B14: EL TENIENTE GERENCIA DE PLANTAS | C14: TCCN-PTE | D14: PLANTA TRATAMIENTO DE ESCORIA | E14: TCCN-PTE-PCH | F14: 7100 - CHANCADO Y ACOPIO | G14: TCCN-PTE-PCH-CNP | H14: CHANCADO PRIMARIO | I14: TCCN-PTE-PCH-CNP-APC | J14: ALIMENTADOR DE PLACAS TOLVA ESCORIA N°1 | L14: TCCN-PTE-PCH-CNP-APC-SME | M14: SISTEMA MECANICO | N14: TCCN-PTE-PCH-CNP-APC-SME-CZP | O14: CADENA ALIMENTADOR DE PLACAS TOLVA 1
A15: TCCN | B15: EL TENIENTE GERENCIA DE PLANTAS | C15: TCCN-PTE | D15: PLANTA TRATAMIENTO DE ESCORIA | E15: TCCN-PTE-PCH | F15: 7100 - CHANCADO Y ACOPIO | G15: TCCN-PTE-PCH-CNP | H15: CHANCADO PRIMARIO | I15: TCCN-PTE-PCH-CNP-APC | J15: ALIMENTADOR DE PLACAS TOLVA ESCORIA N°1 | L15: TCCN-PTE-PCH-CNP-APC-SME | M15: SISTEMA MECANICO | N15: TCCN-PTE-PCH-CNP-APC-SME-PLA | O15: PLACAS ALIMENTADOR DE PLACAS TOLVA 1
... A94: TCCN | B94: EL TENIENTE GERENCIA DE PLANTAS | C94: TCCN-PTE | D94: PLANTA TRATAMIENTO DE ESCORIA | E94: TCCN-PTE-PCH | F94: 7100 - CHANCADO Y ACOPIO | G94: TCCN-PTE-PCH-CNP | H94: CHANCADO PRIMARIO | I94: TCCN-PTE-PCH-CNP-SD4 | J94: SUPRESOR POLVO DSCGA CORREA A ACOPIO N°1 | L94: TCCN-PTE-PCH-CNP-SD4-INS | M94: SISTEMA DE INSTRUMENTACION Y CONTROL | N94: TCCN-PTE-PCH-CNP-SD4-INS-GAB | O94: GABINETE CONTROL Y MONITOR SUP POLV DE 1
A95: TCCN | B95: EL TENIENTE GERENCIA DE PLANTAS | C95: TCCN-PTE | D95: PLANTA TRATAMIENTO DE ESCORIA | E95: TCCN-PTE-PCH | F95: 7100 - CHANCADO Y ACOPIO | G95: TCCN-PTE-PCH-CNP | H95: CHANCADO PRIMARIO | I95: TCCN-PTE-PCH-CNP-DLO | J95: DUCHA LAVAOJOS
A96: TCCN | B96: EL TENIENTE GERENCIA DE PLANTAS | C96: TCCN-PTE | D96: PLANTA TRATAMIENTO DE ESCORIA | E96: TCCN-PTE-PCH | F96: 7100 - CHANCADO Y ACOPIO | G96: TCCN-PTE-PCH-CNP | H96: CHANCADO PRIMARIO | I96: TCCN-PTE-PCH-CNP-TC4 | J96: TECLE MANTENCION ALIMENTADOR DE PLACAS | L96: TCCN-PTE-PCH-CNP-TC4-SIZ | M96: TECLE MANTENCION ALIMENTADOR DE PLACAS | N96: TCCN-PTE-PCH-CNP-TC4-SIZ-MOE | O96: MOTOR ELEC IZAJE TECLE MANT ALIME PLACAS
A97: TCCN | B97: EL TENIENTE GERENCIA DE PLANTAS | C97: TCCN-PTE | D97: PLANTA TRATAMIENTO DE ESCORIA | E97: TCCN-PTE-PCH | F97: 7100 - CHANCADO Y ACOPIO | G97: TCCN-PTE-PCH-CNP | H97: CHANCADO PRIMARIO | I97: TCCN-PTE-PCH-CNP-TC4 | J97: TECLE MANTENCION ALIMENTADOR DE PLACAS | L97: TCCN-PTE-PCH-CNP-TC4-SIZ | M97: TECLE MANTENCION ALIMENTADOR DE PLACAS | N97: TCCN-PTE-PCH-CNP-TC4-SIZ-RED | O97: REDUCTOR IZAJE TECLE MANT ALIMENT PLACAS
A98: TCCN | B98: EL TENIENTE GERENCIA DE PLANTAS | C98: TCCN-PTE | D98: PLANTA TRATAMIENTO DE ESCORIA | E98: TCCN-PTE-PCH | F98: 7100 - CHANCADO Y ACOPIO | G98: TCCN-PTE-PCH-CNP | H98: CHANCADO PRIMARIO | I98: TCCN-PTE-PCH-CNP-TC4 | J98: TECLE MANTENCION ALIMENTADOR DE PLACAS | L98: TCCN-PTE-PCH-CNP-TC4-SIZ | M98: TECLE MANTENCION ALIMENTADOR DE PLACAS | N98: TCCN-PTE-PCH-CNP-TC4-SIZ-TBO | O98: TAMBOR CABLE TECLE MANT ALIMENTAC PLACAS
A99: TCCN | B99: EL TENIENTE GERENCIA DE PLANTAS | C99: TCCN-PTE | D99: PLANTA TRATAMIENTO DE ESCORIA | E99: TCCN-PTE-PCH | F99: 7100 - CHANCADO Y ACOPIO | G99: TCCN-PTE-PCH-CNP | H99: CHANCADO PRIMARIO | I99: TCCN-PTE-PCH-CNP-TC4 | J99: TECLE MANTENCION ALIMENTADOR DE PLACAS | L99: TCCN-PTE-PCH-CNP-TC4-SDZ | M99: SISTEMA DESPLAZAMIENTO MONORRIEL | N99: TCCN-PTE-PCH-CNP-TC4-SDZ-MOE | O99: MOTOR ELEC MONORRIEL TECL MANT ALIM PLAC
A100: TCCN | B100: EL TENIENTE GERENCIA DE PLANTAS | C100: TCCN-PTE | D100: PLANTA TRATAMIENTO DE ESCORIA | E100: TCCN-PTE-PCH | F100: 7100 - CHANCADO Y ACOPIO | G100: TCCN-PTE-PCH-CNP | H100: CHANCADO PRIMARIO | I100: TCCN-PTE-PCH-CNP-TC4 | J100: TECLE MANTENCION ALIMENTADOR DE PLACAS | L100: TCCN-PTE-PCH-CNP-TC4-SCE | M100: SISTEMA ELECTRICO | N100: TCCN-PTE-PCH-CNP-TC4-SCE-BTN | O100: BOTONERA TECLE MANT ALIMENTADOR PLACAS
A101: TCCN | B101: EL TENIENTE GERENCIA DE PLANTAS | C101: TCCN-PTE | D101: PLANTA TRATAMIENTO DE ESCORIA | E101: TCCN-PTE-PCH | F101: 7100 - CHANCADO Y ACOPIO | G101: TCCN-PTE-PCH-CNP | H101: CHANCADO PRIMARIO | I101: TCCN-PTE-PCH-CNP-TC5 | J101: TECLE MANTENCION CHANCADOR | L101: TCCN-PTE-PCH-CNP-TC5-SIZ | M101: SISTEMA IZAJE | N101: TCCN-PTE-PCH-CNP-TC5-SIZ-MOE | O101: MOTOR ELECTRI IZAJE TECLE MANT CHANCADOR
A102: TCCN | B102: EL TENIENTE GERENCIA DE PLANTAS | C102: TCCN-PTE | D102: PLANTA TRATAMIENTO DE ESCORIA | E102: TCCN-PTE-PCH | F102: 7100 - CHANCADO Y ACOPIO | G102: TCCN-PTE-PCH-CNP | H102: CHANCADO PRIMARIO | I102: TCCN-PTE-PCH-CNP-TC5 | J102: TECLE MANTENCION CHANCADOR | L102: TCCN-PTE-PCH-CNP-TC5-SIZ | M102: SISTEMA IZAJE | N102: TCCN-PTE-PCH-CNP-TC5-SIZ-RED | O102: REDUCTOR IZAJE TECLE MANTENCIO CHANCADOR
A103: TCCN | B103: EL TENIENTE GERENCIA DE PLANTAS | C103: TCCN-PTE | D103: PLANTA TRATAMIENTO DE ESCORIA | E103: TCCN-PTE-PCH | F103: 7100 - CHANCADO Y ACOPIO | G103: TCCN-PTE-PCH-CNP | H103: CHANCADO PRIMARIO | I103: TCCN-PTE-PCH-CNP-TC5 | J103: TECLE MANTENCION CHANCADOR | L103: TCCN-PTE-PCH-CNP-TC5-SIZ | M103: SISTEMA IZAJE | N103: TCCN-PTE-PCH-CNP-TC5-SIZ-TBO | O103: TAMBOR CABLE TECLE MANTENCION CHANCADOR
A104: TCCN | B104: EL TENIENTE GERENCIA DE PLANTAS | C104: TCCN-PTE | D104: PLANTA TRATAMIENTO DE ESCORIA | E104: TCCN-PTE-PCH | F104: 7100 - CHANCADO Y ACOPIO | G104: TCCN-PTE-PCH-CNP | H104: CHANCADO PRIMARIO | I104: TCCN-PTE-PCH-CNP-TC5 | J104: TECLE MANTENCION CHANCADOR | L104: TCCN-PTE-PCH-CNP-TC5-SDZ | M104: SISTEMA DESPLAZAMIENTO MONORRIEL | N104: TCCN-PTE-PCH-CNP-TC5-SDZ-MOE | O104: MOTOR ELEC MONORRIEL TECL MANT CHANCADOR
A105: TCCN | B105: EL TENIENTE GERENCIA DE PLANTAS | C105: TCCN-PTE | D105: PLANTA TRATAMIENTO DE ESCORIA | E105: TCCN-PTE-PCH | F105: 7100 - CHANCADO Y ACOPIO | G105: TCCN-PTE-PCH-CNP | H105: CHANCADO PRIMARIO | I105: TCCN-PTE-PCH-CNP-TC5 | J105: TECLE MANTENCION CHANCADOR | L105: TCCN-PTE-PCH-CNP-TC5-SCE | M105: SISTEMA ELECTRICO | N105: TCCN-PTE-PCH-CNP-TC5-SCE-BTN | O105: BOTONERA TECLE MANTENCION CHANCADOR
A106: TCCN | B106: EL TENIENTE GERENCIA DE PLANTAS | C106: TCCN-PTE | D106: PLANTA TRATAMIENTO DE ESCORIA | E106: TCCN-PTE-PCH | F106: 7100 - CHANCADO Y ACOPIO | G106: TCCN-PTE-PCH-CNP | H106: CHANCADO PRIMARIO | I106: TCCN-PTE-PCH-CNP-TC6 | J106: TECLE POLEA COLA CORREA A ACOPIO | L106: TCCN-PTE-PCH-CNP-TC6-SIZ | M106: SISTEMA IZAJE | N106: TCCN-PTE-PCH-CNP-TC6-SIZ-MOE | O106: MOTOR ELEC IZAJE TECL POLEA COLA COR ACO
A107: TCCN | B107: EL TENIENTE GERENCIA DE PLANTAS | C107: TCCN-PTE | D107: PLANTA TRATAMIENTO DE ESCORIA | E107: TCCN-PTE-PCH | F107: 7100 - CHANCADO Y ACOPIO | G107: TCCN-PTE-PCH-CNP | H107: CHANCADO PRIMARIO | I107: TCCN-PTE-PCH-CNP-TC6 | J107: TECLE POLEA COLA CORREA A ACOPIO | L107: TCCN-PTE-PCH-CNP-TC6-SIZ | M107: SISTEMA IZAJE | N107: TCCN-PTE-PCH-CNP-TC6-SIZ-RED | O107: REDUCTOR IZAJE TECL POLEA COLA CORR ACOP
... A224: TCCN | B224: EL TENIENTE GERENCIA DE PLANTAS | C224: TCCN-PTE | D224: PLANTA TRATAMIENTO DE ESCORIA | E224: TCCN-PTE-PSG | F224: 7200 - MOLIENDA ESCORIA | G224: TCCN-PTE-PSG-SAG | H224: MOLIENDA SAG | I224: TCCN-PTE-PSG-SAG-AP2 | J224: ALIMENTADOR DE PLACAS ACOPIO ESCORIA N°2 | L224: TCCN-PTE-PSG-SAG-AP2-SES | M224: SISTEMA ESTRUCTURAL | N224: TCCN-PTE-PSG-SAG-AP2-SES-CH3 | O224: CHUTE RECOLECTOR DE FINOS ALIMENTADR N°2
A225: TCCN | B225: EL TENIENTE GERENCIA DE PLANTAS | C225: TCCN-PTE | D225: PLANTA TRATAMIENTO DE ESCORIA | E225: TCCN-PTE-PSG | F225: 7200 - MOLIENDA ESCORIA | G225: TCCN-PTE-PSG-SAG | H225: MOLIENDA SAG | I225: TCCN-PTE-PSG-SAG-CH7 | J225: CHUTE MOVIL CALIBRACION DESCARGA ESCORIA
A226: TCCN | B226: EL TENIENTE GERENCIA DE PLANTAS | C226: TCCN-PTE | D226: PLANTA TRATAMIENTO DE ESCORIA | E226: TCCN-PTE-PSG | F226: 7200 - MOLIENDA ESCORIA | G226: TCCN-PTE-PSG-SAG | H226: MOLIENDA SAG | I226: TCCN-PTE-PSG-SAG-CH8 | J226: CHUTE FIJO CALIBRACION DESCARGA ESCORIA
A227: TCCN | B227: EL TENIENTE GERENCIA DE PLANTAS | C227: TCCN-PTE | D227: PLANTA TRATAMIENTO DE ESCORIA | E227: TCCN-PTE-PSG | F227: 7200 - MOLIENDA ESCORIA | G227: TCCN-PTE-PSG-SAG | H227: MOLIENDA SAG | I227: TCCN-PTE-PSG-SAG-SDP | J227: SUPRESOR DE POLVO DSCGA ALIMENTADORS N°1 | L227: TCCN-PTE-PSG-SAG-SDP-SHN | M227: SISTEMA HIDRONEUMATICO | N227: TCCN-PTE-PSG-SAG-SDP-SHN-BVV | O227: BANCO VALVULAS SUPR POLVO DSCGA ALIMEN 1
A228: TCCN | B228: EL TENIENTE GERENCIA DE PLANTAS | C228: TCCN-PTE | D228: PLANTA TRATAMIENTO DE ESCORIA | E228: TCCN-PTE-PSG | F228: 7200 - MOLIENDA ESCORIA | G228: TCCN-PTE-PSG-SAG | H228: MOLIENDA SAG | I228: TCCN-PTE-PSG-SAG-SDP | J228: SUPRESOR DE POLVO DSCGA ALIMENTADORS N°1 | L228: TCCN-PTE-PSG-SAG-SDP-INS | M228: SISTEMA DE INSTRUMENTACION Y CONTROL | N228: TCCN-PTE-PSG-SAG-SDP-INS-GAB | O228: GABINETE CONTROL Y MONITOREO SUPR ALIM 1
A229: TCCN | B229: EL TENIENTE GERENCIA DE PLANTAS | C229: TCCN-PTE | D229: PLANTA TRATAMIENTO DE ESCORIA | E229: TCCN-PTE-PSG | F229: 7200 - MOLIENDA ESCORIA | G229: TCCN-PTE-PSG-SAG | H229: MOLIENDA SAG | I229: TCCN-PTE-PSG-SAG-CT1 | J229: CORREA ALIMENTACION MOLINO SAG N°1 | L229: TCCN-PTE-PSG-SAG-CT1-SES | M229: SISTEMA ESTRUCTURAL | N229: TCCN-PTE-PSG-SAG-CT1-SES-GUA | O229: GUARDERAS CORREA ALIMENTAC MOLINO SAG 1
A230: TCCN | B230: EL TENIENTE GERENCIA DE PLANTAS | C230: TCCN-PTE | D230: PLANTA TRATAMIENTO DE ESCORIA | E230: TCCN-PTE-PSG | F230: 7200 - MOLIENDA ESCORIA | G230: TCCN-PTE-PSG-SAG | H230: MOLIENDA SAG | I230: TCCN-PTE-PSG-SAG-CT1 | J230: CORREA ALIMENTACION MOLINO SAG N°1 | L230: TCCN-PTE-PSG-SAG-CT1-SES | M230: SISTEMA ESTRUCTURAL | N230: TCCN-PTE-PSG-SAG-CT1-SES-EST | O230: ESTRUCTURA PPAL CORREA ALIM MOLINO SAG 1
A231: TCCN | B231: EL TENIENTE GERENCIA DE PLANTAS | C231: TCCN-PTE | D231: PLANTA TRATAMIENTO DE ESCORIA | E231: TCCN-PTE-PSG | F231: 7200 - MOLIENDA ESCORIA | G231: TCCN-PTE-PSG-SAG | H231: MOLIENDA SAG | I231: TCCN-PTE-PSG-SAG-CT1 | J231: CORREA ALIMENTACION MOLINO SAG N°1 | L231: TCCN-PTE-PSG-SAG-CT1-SES | M231: SISTEMA ESTRUCTURAL | N231: TCCN-PTE-PSG-SAG-CT1-SES-LPS | O231: LIMPIADORES 1° Y 2° COR ALIM MOLIN SAG 1
A232: TCCN | B232: EL TENIENTE GERENCIA DE PLANTAS | C232: TCCN-PTE | D232: PLANTA TRATAMIENTO DE ESCORIA | E232: TCCN-PTE-PSG | F232: 7200 - MOLIENDA ESCORIA | G232: TCCN-PTE-PSG-SAG | H232: MOLIENDA SAG | I232: TCCN-PTE-PSG-SAG-CT1 | J232: CORREA ALIMENTACION MOLINO SAG N°1 | L232: TCCN-PTE-PSG-SAG-CT1-SES | M232: SISTEMA ESTRUCTURAL | N232: TCCN-PTE-PSG-SAG-CT1-SES-RPD | O232: RASPADOR CORREA ALIMENTAC MOLINO SAG 1
A233: TCCN | B233: EL TENIENTE GERENCIA DE PLANTAS | C233: TCCN-PTE | D233: PLANTA TRATAMIENTO DE ESCORIA | E233: TCCN-PTE-PSG | F233: 7200 - MOLIENDA ESCORIA | G233: TCCN-PTE-PSG-SAG | H233: MOLIENDA SAG | I233: TCCN-PTE-PSG-SAG-CT1 | J233: CORREA ALIMENTACION MOLINO SAG N°1 | L233: TCCN-PTE-PSG-SAG-CT1-SES | M233: SISTEMA ESTRUCTURAL | N233: TCCN-PTE-PSG-SAG-CT1-SES-CHU | O233: CHUTE DE DESCARGA CORREA A MOLINO SAG
A234: TCCN | B234: EL TENIENTE GERENCIA DE PLANTAS | C234: TCCN-PTE | D234: PLANTA TRATAMIENTO DE ESCORIA | E234: TCCN-PTE-PSG | F234: 7200 - MOLIENDA ESCORIA | G234: TCCN-PTE-PSG-SAG | H234: MOLIENDA SAG | I234: TCCN-PTE-PSG-SAG-CT1 | J234: CORREA ALIMENTACION MOLINO SAG N°1 | L234: TCCN-PTE-PSG-SAG-CT1-STR | M234: SISTEMA TRANSPORTE | N234: TCCN-PTE-PSG-SAG-CT1-STR-CTA | O234: CINTA CORREA ALIMENTACION MOLINO SAG N°1
...

Sheet EDE_CARGA
A1: UBICACIÓN TÉCNICA | B1: TIPO DE UBT | C1: NIVEL | D1: DENOMINACIÓN DE LA UBT (40) | E1: TAG | F1: GENERAL | AD1: EMPLAZAMIENTO | AP1: DATOS MT | BC1: ESTRUCTURA
F2: DATOS GENERALES | N2: DATOS DE APROVISIONAMIENTO | X2: GARANTÍA DE CLIENTE | AA2: GARANTÍA DE PROVEEDOR/FABRICANTE | AD2: DATOS DE EMPLAZAMIENTO | AK2: DIRECCIÓN | AP2: IMPUTACIÓN | AX2: RESPONSABLE | BC2: ESTRUCTURA
F3: CLASE | G3: TIPO OBJETO | H3: GRUPO DE AUTORIZACION | I3: PESO DEL OBJETO | J3: UNIDAD DE PESO | K3: TAMAÑO/DIMENSIÓN | L3: NÚMERO DE INVENTARIO | M3: FECHA DE PUESTA EN SERVICIO | N3: VALOR DE ADQUISICIÓN | O3: CLAVE DE MONEDA | P3: FECHA DE ADQUISICIÓN | Q3: FABRICANTE DEL ACTIVO FIJO | R3: PAÍS DE FABRICACIÓN | S3: DENOMINACIÓN DE TIPO DEL FABRICANTE | T3: AÑO DE CONSTRUCCIÓN | U3: MES DE CONSTRUCCIÓN | V3: NÚMERO DE PIEZA DE FABRICANTE | W3: NÚMERO DE SERIE SEGÚN EL FABRICANTE | X3: GARANTÍA/F.CONF | Y3: FIN DE GARANTÍA | Z3: GARANTÍA TIPO | AA3: GARANTÍA/F.CONF | AB3: FIN DE GARANTÍA | AC3: GARANTÍA TIPO | AD3: CENTRO DE EMPLAZAMIENTO | AE3: EMPLAZAMIENTO | AF3: LOCAL | AG3: ÁREA DE EMPRESA | AH3: PUESTO DE TRABAJO RESPONSABLE | AI3: INDICADOR ABC | AJ3: CAMPO DE CLASIFICACIÓN | AK3: NOMBRE | AL3: CALLE | AM3: POBLACIÓN | AN3: TELÉFONO | AO3: FAX | AP3: SOCIEDAD | AQ3: DIVISIÓN | AR3: NÚMERO ACTIVO FIJO | AS3: SUBNÚMERO DE ACTIVO FIJO | AT3: CENTRO DE COSTE | AU3: SOCIEDAD CO | AV3: ELEMENTO PEP | AW3: ORDEN DE LIQUIDACIÓN | AX3: CENTRO DE PLANIFICACIÓN | AY3: GRUPO PLANIFICADOR | AZ3: PUESTO DE TRABAJO RESPONSABLE EN MEDIDAS DE MANTENIMIENTO | BA3: PUESTO DE TRABAJO | BB3: PERFIL DE CATÁLOGO | BC3: IND. ESTRUCTURA | BD3: UBICACION TECNICA SUPERIOR | BE3: DENOMINACIÓN | BF3: POSICIÓN | BG3: UBIC. DE REF. | BH3: TIPO DE MONTAJE | BI3: TIPO
A4: TCCN | B4: P | C4: 1 | D4: EL TENIENTE GERENCIA DE PLANTAS
A5: TCCN-PTE | B5: P | C5: 2 | D5: PLANTA TRATAMIENTO DE ESCORIA
A6: TCCN-PTE-PCH | B6: P | C6: 3 | D6: 7100 - CHANCADO Y ACOPIO
A7: TCCN-PTE-PCH-CNP | B7: P | C7: 4 | D7: CHANCADO PRIMARIO
A8: TCCN-PTE-PCH-CNP-TOL | B8: P | C8: 5 | D8: TOLVA RECEPCION DE ESCORIA N°1 | E8: 07110-TOL-001
A9: TCCN-PTE-PCH-CNP-SLZ | B9: P | C9: 5 | D9: SISTEMA LANZAS TOLVA RECEPCION | E9: 07110-SLZ-001
A10: TCCN-PTE-PCH-CNP-SLZ-SHI | B10: P | C10: 6 | D10: UNIDAD HIDRAULICA | E10: 07110-SLZ-001-01
A11: TCCN-PTE-PCH-CNP-SLZ-SHI-CIH | B11: P | C11: 7 | D11: CILINDROS ACTUADORES LANZAS TOLVA RECEP.
A12: TCCN-PTE-PCH-CNP-SLZ-SHI-BBA | B12: P | C12: 7 | D12: BOMBA HIDR LANZAS TOLVA RECEP.
A13: TCCN-PTE-PCH-CNP-SLZ-SHI-ETQ | B13: P | C13: 7 | D13: ESTANQUE LANZAS TOLVA RECEP.
A14: TCCN-PTE-PCH-CNP-SLZ-SHI-MOE | B14: P | C14: 7 | D14: MOTOR ELEC LANZAS TOLVA RECEP. | E14: 07110-SLZ-001-01M
A15: TCCN-PTE-PCH-CNP-SLZ-SHI-CUH | B15: P | C15: 7 | D15: CALEFACTOR EN DEPOSITO | E15: 07110-SLZ-001-01-1
A16: TCCN-PTE-PCH-CNP-SLZ-SME | B16: P | C16: 6 | D16: SISTEMA MECANICO
A17: TCCN-PTE-PCH-CNP-SLZ-SME-LAN | B17: P | C17: 7 | D17: SET DE LANZAS
A18: TCCN-PTE-PCH-CNP-SLZ-SME-CRL | B18: P | C18: 7 | D18: CARRO LANZAS
A19: TCCN-PTE-PCH-CNP-SLZ-SES | B19: P | C19: 6 | D19: SISTEMA ESTRUCTURAL
A20: TCCN-PTE-PCH-CNP-SLZ-SES-CHU | B20: P | C20: 7 | D20: CHUTE SISTEMA DE LANZAS | E20: 07110-SLZ-001-02
A21: TCCN-PTE-PCH-CNP-APC | B21: P | C21: 5 | D21: ALIMENTADOR DE PLACAS TOLVA ESCORIA N°1 | E21: 07120-APC-001
A22: TCCN-PTE-PCH-CNP-APC-SME | B22: P | C22: 6 | D22: SISTEMA MECANICO
A23: TCCN-PTE-PCH-CNP-APC-SME-RUE | B23: P | C23: 7 | D23: RUEDA DE COLA ALIMENTADOR PLACAS TOLVA 1
A24: TCCN-PTE-PCH-CNP-APC-SME-PNN | B24: P | C24: 7 | D24: PIÑON DE CABEZA ALIMENTAD PLACAS TOLVA 1
A25: TCCN-PTE-PCH-CNP-APC-SME-CZP | B25: P | C25: 7 | D25: CADENA ALIMENTADOR DE PLACAS TOLVA 1
A26: TCCN-PTE-PCH-CNP-APC-SME-PLA | B26: P | C26: 7 | D26: PLACAS ALIMENTADOR DE PLACAS TOLVA 1
A27: TCCN-PTE-PCH-CNP-APC-INS | B27: P | C27: 6 | D27: SISTEMA DE INSTRUMENTACION Y CONTROL
A28: TCCN-PTE-PCH-CNP-APC-INS-PE1 | B28: P | C28: 7 | D28: PARADA DE EMERGENCIA RS-2 (PULL CORD) | E28: 07120-HSS-0113A
A29: TCCN-PTE-PCH-CNP-APC-INS-PE2 | B29: P | C29: 7 | D29: PARADA DE EMERGENCIA RS-2 (PULL CORD) | E29: 07120-HSS-0113B
A30: TCCN-PTE-PCH-CNP-APC-INS-SA1 | B30: P | C30: 7 | D30: SENSOR DE ATOLLO – CT105 TIPO W
A31: TCCN-PTE-PCH-CNP-APC-INS-SA2 | B31: P | C31: 7 | D31: SENSOR DE ATOLLO – CT201G TIPO W
A32: TCCN-PTE-PCH-CNP-APC-INS-SV1 | B32: P | C32: 7 | D32: SENSOR DE VELOCIDAD CERO - RMS-1G TIP W | E32: 07120-SE/SSL-0110
A33: TCCN-PTE-PCH-CNP-APC-INS-SV2 | B33: P | C33: 7 | D33: SENSOR DE VELOCIDAD CERO – RMS 30S TIP W
A34: TCCN-PTE-PCH-CNP-APC-INS-SS1 | B34: P | C34: 7 | D34: SENSOR TEMPERATURA DESCANSOS PT-100 | E34: 07120-TE/TT-0114A
A35: TCCN-PTE-PCH-CNP-APC-INS-SS2 | B35: P | C35: 7 | D35: SENSOR TEMPERATURA DESCANSOS PT-101 | E35: 07120-TE/TT-0114B
A36: TCCN-PTE-PCH-CNP-APC-INS-BY1 | B36: P | C36: 7 | D36: BOCINA 876-N5 TIPO W | E36: 07120-YA-0107
A37: TCCN-PTE-PCH-CNP-APC-INS-BLZ | B37: P | C37: 7 | D37: BALIZA SINALIZ. 52 A-N5-40WH-WBR TIPO W | E37: 07120-YL-0107
A38: TCCN-PTE-PCH-CNP-APC-SLU | B38: P | C38: 6 | D38: UNIDAD DE LUBRICACION | E38: 07120-APC-001-03
A39: TCCN-PTE-PCH-CNP-APC-SLU-BBA | B39: P | C39: 7 | D39: BOMBA ALIMENTADOR DE PLACAS TOLVA 1
A40: TCCN-PTE-PCH-CNP-APC-SLU-MOE | B40: P | C40: 7 | D40: MOTOR SISTEMA DE LUBRICACION A GRASA | E40: 07120-APC-001-03M
...

Sheet datos
A1: Caracteres (sin guiones) | B1: Nivel | C1: Restar "-" | D1: Carac.niv.sup.
A2: 0 | B2: 0 | C2: 7
A3: 4 | B3: 1 | C3: 6
A4: 7 | B4: 2 | C4: 5 | D4: 4
A5: 10 | B5: 3 | C5: 4 | D5: 8
A6: 13 | B6: 4 | C6: 3 | D6: 12
A7: 16 | B7: 5 | C7: 2 | D7: 16
A8: 19 | B8: 6 | C8: 1 | D8: 20
A9: 22 | B9: 7 | C9: 0 | D9: 24
A10: 25 | B10: 8 | C10: 0 | D10: 28
A11: 28 | B11: 9 | C11: 0
A12: 31 | B12: 10 | C12: 0
