Workbook
Name ____tc1: [1]GG!$J$2
Name ___EPP2: [2]EPP!$J$22
Name ___f: 0.8
Name ___TSP4: [3]TSP4!$A$2:$G$165
Name ___VIZ4: [4]VIZ4!$A$2:$J$416
Name ___VIZ7: [4]VIZ7!$A$2:$J$476
Name __123Graph_A: [5]Zn!#REF!
Name __123Graph_ASECPRED: [6]LEAD!#REF!
Name __123Graph_BSECOND: [6]LEAD!#REF!
Name __123Graph_CSECOND: [6]LEAD!#REF!
Name __EPP2: [2]EPP!$J$22
Name __f: 0.8
Name __tc1: [7]GG!$J$2
Name __TSP4: [3]TSP4!$A$2:$G$165
Name __VIZ4: [4]VIZ4!$A$2:$J$416
Name __VIZ7: [4]VIZ7!$A$2:$J$476
Name _10__123Graph_ACHART_9: '[8]Load 2'!#REF!
Name _12__123Graph_BCHART_15: '[8]Material Forecast'!#REF!
Name _14__123Graph_BCHART_16: '[8]Material Forecast'!#REF!
Name _16__123Graph_BCHART_9: '[8]Load 2'!#REF!
Name _18__123Graph_CCHART_11: '[8]Material Forecast'!#REF!
Name _2__123Graph_ACHART_11: '[8]Material Forecast'!#REF!
Name _20__123Graph_CCHART_12: '[8]Material Forecast'!#REF!
Name _22__123Graph_CCHART_15: '[8]Material Forecast'!#REF!
Name _24__123Graph_CCHART_16: '[8]Material Forecast'!#REF!
Name _26__123Graph_DCHART_15: '[8]Material Forecast'!#REF!
Name _28__123Graph_ECHART_15: '[8]Material Forecast'!#REF!
Name _30__123Graph_XCHART_12: '[8]Material Forecast'!#REF!
Name _32__123Graph_XCHART_15: '[8]Material Forecast'!#REF!
Name _34__123Graph_XCHART_16: '[8]Material Forecast'!#REF!
Name _4__123Graph_ACHART_12: '[8]Material Forecast'!#REF!
Name _6__123Graph_ACHART_15: '[8]Material Forecast'!#REF!
Name _8__123Graph_ACHART_16: '[8]Material Forecast'!#REF!
Name _EPP2: [2]EPP!$J$22
Name _f: 0.8
Name _Order1: 255
Name _Order2: 255
Name _Regression_Out: '[9]loading equipment'!#REF!
Name _Regression_X: '[9]loading equipment'!$O$118:$O$120
Name _Regression_Y: '[9]loading equipment'!$Q$118:$Q$120
Name _res1: '[10]Resumen Ejec'!$B$2:$G$66
Name _res2: '[10]Resumen Ejec'!$B$70:$G$125
Name _res3: '[10]Resumen Ejec'!$B$142:$E$189
Name _res4: '[10]Resumen Ejec'!$B$198:$D$261
Name _tc1: [11]GG!$J$2
Name _TSP4: [3]TSP4!$A$2:$G$165
Name _VIZ4: [4]VIZ4!$A$2:$J$416
Name _VIZ7: [4]VIZ7!$A$2:$J$476
Name accesorio: [2]Insumos!$A$105:$E$129
Name accesorios: [12]Insumos!$A$105:$G$129
Name aceros: [2]Insumos!$A$77:$F$100
Name aguilar: [13]Parametros!#REF!
Name avance: [2]Insumos!$J$1
Name b: [13]Parametros!#REF!
Name banana: '[15]Balance Sheet Consolidated'!$C$5:$J$59
Name BSE: [16]BBSS!$K$38
Name Cálculos: [17]ANALISIS!$A$112:$L$198
Name cambio: '[18]GGAESA (2)'!$F$1
Name camion2: [13]Parametros!#REF!
Name categorias: [2]Insumos!$H$3:$J$21

Sheet Estimación de pérdidas
B2: Budget Salares Norte
C4: Y01 | D4: Y02 | E4: Y03 | F4: Y04 | G4: Y05 | H4: Y06 | I4: Y07 | J4: Y08 | K4: Y09 | L4: Y10 | M4: Y11 | N4: Y12 | O4: total
B5: Beneficio ton | C5: 1276070 | D5: 2000000 | E5: 2000000 | F5: 2000000 | G5: 2000000 | H5: 2000000 | I5: 2000000 | J5: 2000000 | K5: 2000000 | L5: 2000000 | M5: 2000000 | N5: 890000 | O5: =SUM(C5:N5) -> 22166070
B6: Oz Au | C6: 333918.29 | D6: 546538.54 | E6: 543926.66 | F6: 390327.47 | G6: 355319.26 | H6: 316562.44 | I6: 434351.76 | J6: 103293.13 | K6: 86389.12 | L6: 61957.465 | M6: 59278.731 | N6: 45324.223 | O6: =SUM(C6:N6) -> 3277187.1
B7: Oz Ag | C7: 1329033.3 | D7: 3609336.6 | E7: 3822391.4 | F7: 2418013.2 | G7: 3505080.7 | H7: 2433967.2 | I7: 1519056.7 | J7: 3495626.2 | K7: 1139234.1 | L7: 2664213.9 | M7: 611561.53 | N7: 184386.94 | O7: =SUM(C7:N7) -> 26731902
B8: Precious Oz Gold (US$) | C8: 1300 | D8: =+C8 -> 1300 | E8: =+D8 -> 1300 | F8: =+E8 -> 1300 | G8: =+F8 -> 1300 | H8: =+G8 -> 1300 | I8: =+H8 -> 1300 | J8: =+I8 -> 1300 | K8: =+J8 -> 1300 | ... N8: =+M8 -> 1300
B9: Precious Oz Silver (US$) | C9: 17.5 | D9: =+C9 -> 17.5 | E9: =+D9 -> 17.5 | F9: =+E9 -> 17.5 | G9: =+F9 -> 17.5 | H9: =+G9 -> 17.5 | I9: =+H9 -> 17.5 | J9: =+I9 -> 17.5 | K9: =+J9 -> 17.5 | ... N9: =+M9 -> 17.5
B10: Oz Equivalentes | C10: =+C6+C7/(C8/C9) -> 351809.12 | D10: =+D6+D7/(D8/D9) -> 595125.76 | E10: =+E6+E7/(E8/E9) -> 595381.93 | F10: =+F6+F7/(F8/F9) -> 422877.65 | G10: =+G6+G7/(G8/G9) -> 402503.04 | H10: =+H6+H7/(H8/H9) -> 349327.39 | I10: =+I6+I7/(I8/I9) -> 454800.6 | J10: =+J6+J7/(J8/J9) -> 150349.64 | ... N10: =+N6+N7/(N8/N9) -> 47806.355 | O10: =SUM(C10:N10) -> 3637039.6
A12: Ingresos | B12: Ingresos Ventas
B13: Ingresos Au US$ | C13: =+C8*C6 -> 4.3409377e+08 | D13: =+D8*D6 -> 7.105001e+08 | E13: =+E8*E6 -> 7.0710466e+08 | F13: =+F8*F6 -> 5.0742571e+08 | G13: =+G8*G6 -> 4.6191503e+08 | H13: =+H8*H6 -> 4.1153118e+08 | I13: =+I8*I6 -> 5.6465729e+08 | J13: =+J8*J6 -> 1.3428107e+08 | ... N13: =+N8*N6 -> 58921490 | O13: =SUM(C13:N13) -> 4260343230
B14: Ingresos Ag US$ | C14: =+C9*C7 -> 23258083 | D14: =+D9*D7 -> 63163390 | E14: =+E9*E7 -> 66891849 | F14: =+F9*F7 -> 42315230 | G14: =+G9*G7 -> 61338912 | H14: =+H9*H7 -> 42594427 | I14: =+I9*I7 -> 26583492 | J14: =+J9*J7 -> 61173458 | ... N14: =+N9*N7 -> 3226771.4 | O14: =SUM(C14:N14) -> 4.6780828e+08
B15: Total Ingresos US$ | C15: =+C14+C13 -> 4.5735186e+08 | D15: =+D14+D13 -> 7.7366349e+08 | E15: =+E14+E13 -> 7.7399651e+08 | F15: =+F14+F13 -> 5.4974094e+08 | G15: =+G14+G13 -> 5.2325395e+08 | H15: =+H14+H13 -> 4.541256e+08 | I15: =+I14+I13 -> 5.9124078e+08 | J15: =+J14+J13 -> 1.9545453e+08 | ... N15: =+N14+N13 -> 62148262 | O15: =SUM(C15:N15) -> 4728151509
B16: Total Ingresos MUS$ | C16: =+C15/1000000 -> 457.35186 | D16: =+D15/1000000 -> 773.66349 | E16: =+E15/1000000 -> 773.99651 | F16: =+F15/1000000 -> 549.74094 | G16: =+G15/1000000 -> 523.25395 | H16: =+H15/1000000 -> 454.1256 | I16: =+I15/1000000 -> 591.24078 | J16: =+J15/1000000 -> 195.45453 | ... N16: =+N15/1000000 -> 62.148262
A19: Egresos | B19: Egresos Operacionales
B20: Gestión Operacional MUS$ | C20: =+C4 -> Y01 | D20: =+D4 -> Y02 | E20: =+E4 -> Y03 | F20: =+F4 -> Y04 | G20: =+G4 -> Y05 | H20: =+H4 -> Y06 | I20: =+I4 -> Y07 | J20: =+J4 -> Y08 | ... N20: =+N4 -> Y12 | O20: Total MUS$ | P20: USD/ton ore | Q20: USD/Oz Equivalente
B21: G&A | C21: 39.8 | D21: 32.15 | E21: 32.15 | F21: 31.92 | G21: 31.92 | H21: 32.03 | I21: 30.49 | J21: 25.3 | K21: 24.77 | L21: 20.96 | M21: 12.66 | N21: 3.73 | O21: =SUM(C21:N21)*1000000 -> 317880000 | P21: =+O21/$O$5 -> 14.340837 | Q21: =+O21/$O$10 -> 87.400753
B22: Mining | C22: 82.57 | D22: 94.09 | E22: 100.27 | F22: 106.94 | G22: 106.79 | H22: 101.06 | I22: 71.57 | J22: 0 | K22: 0 | L22: 0 | M22: 0 | N22: 0 | O22: =SUM(C22:N22)*1000000 -> 663290000 | P22: =+O22/$O$5 -> 29.923663 | Q22: =+O22/$O$10 -> 182.37085
B23: Ore Re-handle | C23: 0.94 | D23: 1.56 | E23: 1.59 | F23: 1.64 | G23: 1.82 | H23: 1.42 | I23: 1.63 | J23: 6.42 | K23: 6.34 | L23: 6.34 | M23: 6.21 | N23: 3.17 | O23: =SUM(C23:N23)*1000000 -> 39080000 | P23: =+O23/$O$5 -> 1.763055 | Q23: =+O23/$O$10 -> 10.745003
B24: Processing | C24: 44.2 | D24: 59.48 | E24: 59.7 | F24: 59.94 | G24: 61.71 | H24: 57.77 | I24: 57.92 | J24: 58.77 | K24: 54.32 | L24: 55.91 | M24: 53.92 | N24: 26.37 | O24: =SUM(C24:N24)*1000000 -> 650010000 | P24: =+O24/$O$5 -> 29.324549 | Q24: =+O24/$O$10 -> 178.71953
B25: Tailings Transport | C25: 1.9 | D25: 2.65 | E25: 2.7 | F25: 2.75 | G25: 2.99 | H25: 2.55 | I25: 2.78 | J25: 4.6 | K25: 4.5 | L25: 4.6 | M25: 4.45 | N25: 2.22 | O25: =SUM(C25:N25)*1000000 -> 38690000 | P25: =+O25/$O$5 -> 1.7454605 | Q25: =+O25/$O$10 -> 10.637772
B26: Total MUS$ | C26: =SUM(C21:C25) -> 169.41 | D26: =SUM(D21:D25) -> 189.93 | E26: =SUM(E21:E25) -> 196.41 | F26: =SUM(F21:F25) -> 203.19 | G26: =SUM(G21:G25) -> 205.23 | H26: =SUM(H21:H25) -> 194.83 | I26: =SUM(I21:I25) -> 164.39 | J26: =SUM(J21:J25) -> 95.09 | ... N26: =SUM(N21:N25) -> 35.49 | O26: =SUM(C26:N26)*1000000 -> 1708950000 | P26: =+O26/$O$5 -> 77.097564
B28: Cash Cost US$/Oz equivalentes | C28: =+C26*1000000/C10 -> 481.53953 | D28: =+D26*1000000/D10 -> 319.14263 | E28: =+E26*1000000/E10 -> 329.88908 | F28: =+F26*1000000/F10 -> 480.49359 | G28: =+G26*1000000/G10 -> 509.88435 | H28: =+H26*1000000/H10 -> 557.72896 | I28: =+I26*1000000/I10 -> 361.45511 | J28: =+J26*1000000/J10 -> 632.45911 | ... N28: =+N26*1000000/N10 -> 742.36992 | O28: =+O26/O10 -> 469.8739 | Q28: =SUM(Q21:Q26) -> 469.8739
B30: Total Egresos US$ | C30: =+C26*1000000*-1 -> -169410000 | D30: =+D26*1000000*-1 -> -189930000 | E30: =+E26*1000000*-1 -> -196410000 | F30: =+F26*1000000*-1 -> -203190000 | G30: =+G26*1000000*-1 -> -205230000 | H30: =+H26*1000000*-1 -> -194830000 | I30: =+I26*1000000*-1 -> -164390000 | J30: =+J26*1000000*-1 -> -95090000 | ... N30: =+N26*1000000*-1 -> -35490000 | O30: =SUM(C30:N30) -> -1708950000
A32: Margen | B32: Margen Contribución Operacional US$ | C32: =+C15+C30 -> 2.8794186e+08 | D32: =+D15+D30 -> 5.8373349e+08 | E32: =+E15+E30 -> 5.7758651e+08 | F32: =+F15+F30 -> 3.4655094e+08 | G32: =+G15+G30 -> 3.1802395e+08 | H32: =+H15+H30 -> 2.592956e+08 | I32: =+I15+I30 -> 4.2685078e+08 | J32: =+J15+J30 -> 1.0036453e+08 | ... N32: =+N15+N30 -> 26658262 | O32: =SUM(C32:N32) -> 3019201509
B33: Margen Contribución Operacional MUS$ | C33: =+C32/1000000 -> 287.94186 | D33: =+D32/1000000 -> 583.73349 | E33: =+E32/1000000 -> 577.58651 | F33: =+F32/1000000 -> 346.55094 | G33: =+G32/1000000 -> 318.02395 | H33: =+H32/1000000 -> 259.2956 | I33: =+I32/1000000 -> 426.85078 | J33: =+J32/1000000 -> 100.36453 | ... N33: =+N32/1000000 -> 26.658262
D34: =+D32/D15 -> 0.75450567 | E34: =+E32/E15 -> 0.74623917 | F34: =+F32/F15 -> 0.63038955 | G34: =+G32/G15 -> 0.60778127 | H34: =+H32/H15 -> 0.57097773 | I34: =+I32/I15 -> 0.72195761 | J34: =+J32/J15 -> 0.51349299 | K34: =+K32/K15 -> 0.31996119 | ... N34: =+N32/N15 -> 0.42894621
A39: Op. Data | B39: Datos Operacionales | C39: Y01 | D39: Y02 | E39: Y03 | F39: Y04 | G39: Y05 | H39: Y06 | I39: Y07 | J39: Y08 | K39: Y09 | L39: Y10 | M39: Y11 | N39: Y12
B40: Utilización % | C40: 91.3 | D40: 91.3 | E40: 91.3 | F40: 91.3 | G40: 91.3 | H40: 91.3 | I40: 91.3 | J40: 91.3 | K40: 91.3 | L40: 91.3 | M40: 91.3 | N40: 91.3
B41: días año | C41: 365 | D41: 365 | E41: 365 | F41: 365 | G41: 365 | H41: 365 | I41: 365 | J41: 365 | K41: 365 | L41: 365 | M41: 365 | N41: 365
B42: dias efectivos | C42: =+C41*C40/100 -> 333.245 | D42: =+D41*D40/100 -> 333.245 | E42: =+E41*E40/100 -> 333.245 | F42: =+F41*F40/100 -> 333.245 | G42: =+G41*G40/100 -> 333.245 | H42: =+H41*H40/100 -> 333.245 | I42: =+I41*I40/100 -> 333.245 | J42: =+J41*J40/100 -> 333.245 | ... N42: =+N41*N40/100 -> 333.245
B43: Oz día Au | C43: =+C6/C42 -> 1002.0204 | D43: =+D6/D42 -> 1640.0502 | E43: =+E6/E42 -> 1632.2125 | F43: =+F6/F42 -> 1171.2928 | G43: =+G6/G42 -> 1066.2403 | H43: =+H6/H42 -> 949.93907 | I43: =+I6/I42 -> 1303.4007 | J43: =+J6/J42 -> 309.96154 | ... N43: =+N6/N42 -> 136.00871
B44: Oz hr Au | C44: =+C43/(24*C40%) -> 45.729299 | D44: =+D43/(24*D40%) -> 74.847126 | E44: =+E43/(24*E40%) -> 74.489436 | F44: =+F43/(24*F40%) -> 53.4544 | G44: =+G43/(24*G40%) -> 48.66011 | H44: =+H43/(24*H40%) -> 43.352458 | I44: =+I43/(24*I40%) -> 59.483419 | J44: =+J43/(24*J40%) -> 14.145744 | ... N44: =+N43/(24*N40%) -> 6.2070423
A45: Ingresos Hr | B45: Ingreso hr Au US$ | C45: =+C44*C8 -> 59448.089 | D45: =+D44*D8 -> 97301.264 | E45: =+E44*E8 -> 96836.267 | F45: =+F44*F8 -> 69490.72 | G45: =+G44*G8 -> 63258.143 | H45: =+H44*H8 -> 56358.196 | I45: =+I44*I8 -> 77328.445 | J45: =+J44*J8 -> 18389.467 | ... N45: =+N44*N8 -> 8069.155
B46: Oz día Ag | C46: =+C7/C42 -> 3988.1569 | D46: =+D7/D42 -> 10830.88 | E46: =+E7/E42 -> 11470.214 | F46: =+F7/F42 -> 7255.9623 | G46: =+G7/G42 -> 10518.029 | H46: =+H7/H42 -> 7303.8372 | I46: =+I7/I42 -> 4558.3781 | J46: =+J7/J42 -> 10489.658 | ... N46: =+N7/N42 -> 553.30744
B47: Oz hr Ag US$ | C47: =+C46/(24*C40%) -> 182.00789 | D47: =+D46/(24*D40%) -> 494.28988 | E47: =+E46/(24*E40%) -> 523.46722 | F47: =+F46/(24*F40%) -> 331.14103 | G47: =+G46/(24*G40%) -> 480.01229 | H47: =+H46/(24*H40%) -> 333.32591 | I47: =+I46/(24*I40%) -> 208.03113 | J47: =+J46/(24*J40%) -> 478.71752 | ... N47: =+N46/(24*N40%) -> 25.251344
B48: Ingreso hr Ag | C48: =+C47*C9 -> 3185.1381 | D48: =+D47*D9 -> 8650.0729 | E48: =+E47*E9 -> 9160.6763 | F48: =+F47*F9 -> 5794.9681 | G48: =+G47*G9 -> 8400.2151 | H48: =+H47*H9 -> 5833.2033 | I48: =+I47*I9 -> 3640.5447 | J48: =+J47*J9 -> 8377.5565 | ... N48: =+N47*N9 -> 441.89851
B49: Ingreso total Hr Au, Ag | C49: =+C48+C45 -> 62633.227 | D49: =+D48+D45 -> 105951.34 | E49: =+E48+E45 -> 105996.94 | F49: =+F48+F45 -> 75285.688 | G49: =+G48+G45 -> 71658.358 | H49: =+H48+H45 -> 62191.399 | I49: =+I48+I45 -> 80968.99 | J49: =+J48+J45 -> 26767.024 | ... N49: =+N48+N45 -> 8511.0536
B50: Oz Equivalentes día | C50: =+C10/C42 -> 1055.7071 | D50: =+D10/D42 -> 1785.8505 | E50: =+E10/E42 -> 1786.6193 | F50: =+F10/F42 -> 1268.9692 | G50: =+G10/G42 -> 1207.8292 | H50: =+H10/H42 -> 1048.26 | I50: =+I10/I42 -> 1364.7635 | J50: =+J10/J42 -> 451.16848 | ... N50: =+N10/N42 -> 143.45708
B51: Oz Equivalentes hr | C51: =+C50/(24*C40%) -> 48.179405 | D51: =+D50/(24*D40%) -> 81.501029 | E51: =+E50/(24*E40%) -> 81.53611 | F51: =+F50/(24*F40%) -> 57.912067 | G51: =+G50/(24*G40%) -> 55.121814 | H51: =+H50/(24*H40%) -> 47.839538 | I51: =+I50/(24*I40%) -> 62.283838 | J51: =+J50/(24*J40%) -> 20.590018 | ... N51: =+N50/(24*N40%) -> 6.5469643
B52: Ingreso Oz Equivalentes hr | C52: =+C51*C8 -> 62633.227 | D52: =+D51*D8 -> 105951.34 | E52: =+E51*E8 -> 105996.94 | F52: =+F51*F8 -> 75285.688 | G52: =+G51*G8 -> 71658.358 | H52: =+H51*H8 -> 62191.399 | I52: =+I51*I8 -> 80968.99 | J52: =+J51*J8 -> 26767.024 | ... N52: =+N51*N8 -> 8511.0536
...

Sheet Plantilla criticidad de activos
A1: Análisis de criticidad de activos / equipos
A2: Sub área | B2: Sistema | C2: Descripción UT | D2: Cod. TAG UT | E2: Descripción UT | F2: Función principal | G2: Evento / Falla | H2: Consecuencia de falla / evento | I2: # equipos instalados | J2: # equipos requeridos para operación | K2: Redundancia | L2: Tipo Redundancia | M2: Down time equipo (Días) | N2: Afectación a capacidad del proceso | O2: Factor de utilización | P2: Demora en afectación del proceso (Horas) | Q2: Pérdida del proceso [Tiempo en horas] | R2: Pérdida del proceso [USD] | S2: ¿Es SCE*? Safety Critical Equipment | T2: Evaluación de Riesgo | AH2: Probabilidad | AI2: Criticidad
T3: Probabilidad / Frecuencia de falla | U3: Consecuencias consideradas | Z3: Consecuencia dominante | AA3: Consideración de riesgo / criticidad | AB3: Coeficiente de riesgo | AC3: Valoración de riesgo | AH3: 5-Casi seguro | AI3: Moderado | AJ3: 5
L4: Tipo Redundancia | M4: Down time equipo (Días) | N4: Afectación a capacidad del proceso | O4: Factor de utilización | P4: Demora en afectación del proceso (Horas) | Q4: Pérdida del proceso [Tiempo en horas] | R4: Pérdida del proceso [USD] | U4: Margen operacional | V4: Costo operacional | W4: Seguridad y Salud | X4: Medio Ambiente | Y4: RSC (Comunidad / Imagen / Cumplimento legal) | AH4: 4-Probable | AI4: Bajo | AJ4: 4
A5: 2100 Chancado Primario & Acopio Mineral Mina | B5: 2110 Estación de chancador primario | C5: Acumulador aire de Chancado | D5: 2110AR0003 | E5: Acumulador de aire Chancado | F5: Acumular el aire comprimido proveniente del compresor 2110CP0003 y a ser distribuido a supresor de polvo 2110DT0001 | G5: Rotura de acumulador | H5: No afectación a producción, Área contaminada de polvo sin efectos posteriores en salud de personas, Costos de cambio de acumulador | I5: 1 | J5: 1 | K5: =+IF(I5="","",IF((I5-J5)>0,"Si","No")) -> No | L5: Ninguna | M5: 0.25 | N5: 0 | O5: 70 | P5: 10 | Q5: =+IF(M5="","",(IF(((M5*24)-P5)<0,0,(M5*24)-P5)*N5)) -> 0 | R5: =+(IF(((M5*24)-P5)<0,0,((M5*24)-P5)*'Estimación de pérdidas'!$F$72))*N5 -> 0 | S5: No | T5: 2-Improbable | U5: =+IF(R5="","",IF(R5<50001,1,IF(R5<200001,2,IF(R5<500001,3,IF(R5<1000001,4,5))))) -> 1 | V5: 1 | Z5: =MAX(U5:Y5) -> 1 | AA5: =IF(Z5=1,VLOOKUP(T5,$AH$3:$AI$7,2,FALSE),IF(Z5=2,VLOOKUP(T5,$AH$8:$AI$12,2, FALSE),IF(Z5=3,VLOOKUP(T5,$AH$13:$AI$17,2,FALSE),IF(Z5=4,VLOOKUP(T5,$AH$18:$AI$22,2,FALSE),IF(Z5=5,VLOOKUP(T5,$AH$23:$AI$27,2,FALSE),""))))) -> Bajo | AB5: =IF(T5="1-Raro",IF(Z5=1,1,IF(Z5=2,3,IF(Z5=3,6,IF(Z5=4,10,15)))),IF(T5="2-Improbable",IF(Z5=1,2,IF(Z5=2,5,IF(Z5=3,9,IF(Z5=4,14,19)))),IF(T5="3-Posible",IF(Z5=1,4,IF(Z5=2,8,IF(Z5=3,13,IF(Z5=4,18,21)))),IF(T5="4-Probable",IF(Z5=1,7,IF(Z5=2,12,IF(Z5=3,17,IF(Z5=4,22,23)))),IF(T5="5-Casi Seguro",IF(Z5=1,11,IF(Z5=2,16,IF(Z5=3,20,IF(Z5=4,24,25))))))))) -> 2 | AC5: =((VLOOKUP(T5,$AH$3:$AJ$7,3,FALSE)*SQRT(U5^2+V5^2+W5^2+X5^2+Y5^2))/(5*SQRT((5)*5^2))) -> 0.050596443 | AH5: 3-Posible | AI5: Bajo | AJ5: 3
A6: 2100 Chancado Primario & Acopio Mineral Mina | B6: 2110 Estación de chancador primario | C6: Tolva Room | D6: 2110BN0001 | E6: Tolva room | F6: Recepcionar material de camiones (40 Ton) provenientes de mina, tiene una plataforma de descarga y una capacidad es de 80 toneladas (2 camiones) para alimentar chancador de mandíbulas | G6: Soltura de revestimientos internos de tolva por presencia de inchancables (puntas de pala) en tolva provenientes de camiones de mina | H6: Afectación a producción, Parada de chancador y alimentación de Stock pile para remover inchancables, Costos reparación de tolva | I6: 1 | J6: 1 | K6: =+IF(I6="","",IF((I6-J6)>0,"Si","No")) -> No | L6: Ninguna | M6: 1 | N6: 1 | O6: 70 | P6: 10 | Q6: =+IF(M6="","",(IF(((M6*24)-P6)<0,0,(M6*24)-P6)*N6)) -> 14 | R6: =+(IF(((M6*24)-P6)<0,0,((M6*24)-P6)*'Estimación de pérdidas'!$F$72))*N6 -> 807493.05 | S6: No | T6: 4-Probable | U6: =+IF(R6="","",IF(R6<50001,1,IF(R6<200001,2,IF(R6<500001,3,IF(R6<1000001,4,5))))) -> 4 | V6: 1 | Z6: =MAX(U6:Y6) -> 4 | AA6: =IF(Z6=1,VLOOKUP(T6,$AH$3:$AI$7,2,FALSE),IF(Z6=2,VLOOKUP(T6,$AH$8:$AI$12,2, FALSE),IF(Z6=3,VLOOKUP(T6,$AH$13:$AI$17,2,FALSE),IF(Z6=4,VLOOKUP(T6,$AH$18:$AI$22,2,FALSE),IF(Z6=5,VLOOKUP(T6,$AH$23:$AI$27,2,FALSE),""))))) -> Alto | AB6: =IF(T6="1-Raro",IF(Z6=1,1,IF(Z6=2,3,IF(Z6=3,6,IF(Z6=4,10,15)))),IF(T6="2-Improbable",IF(Z6=1,2,IF(Z6=2,5,IF(Z6=3,9,IF(Z6=4,14,19)))),IF(T6="3-Posible",IF(Z6=1,4,IF(Z6=2,8,IF(Z6=3,13,IF(Z6=4,18,21)))),IF(T6="4-Probable",IF(Z6=1,7,IF(Z6=2,12,IF(Z6=3,17,IF(Z6=4,22,23)))),IF(T6="5-Casi Seguro",IF(Z6=1,11,IF(Z6=2,16,IF(Z6=3,20,IF(Z6=4,24,25))))))))) -> 22 | AC6: =((VLOOKUP(T6,$AH$3:$AJ$7,3,FALSE)*SQRT(U6^2+V6^2+W6^2+X6^2+Y6^2))/(5*SQRT((5)*5^2))) -> 0.29502542 | AH6: 2-Improbable | AI6: Bajo | AJ6: 2
A7: 2100 Chancado Primario & Acopio Mineral Mina | B7: 2110 Estación de chancador primario | C7: Alimentador bandeja Chancador | D7: 2110FE0021 | E7: Alimentador bandeja chancado | F7: Descargar material proveniente de Tolva Room hacia el chute 2110-CH-0002 que alimenta chancador de mandíbulas | G7: Rotura de bandeja por inchancables | H7: No afectación a producción, Suspensión alimentación a tolva room, Parada de chancador y alimentación de Stock pile, Costo por cambio de bandeja | I7: 1 | J7: 1 | K7: =+IF(I7="","",IF((I7-J7)>0,"Si","No")) -> No | L7: Ninguna | M7: 0.25 | N7: 1 | O7: 70 | P7: 10 | Q7: =+IF(M7="","",(IF(((M7*24)-P7)<0,0,(M7*24)-P7)*N7)) -> 0 | R7: =+(IF(((M7*24)-P7)<0,0,((M7*24)-P7)*'Estimación de pérdidas'!$F$72))*N7 -> 0 | S7: No | T7: 4-Probable | U7: =+IF(R7="","",IF(R7<50001,1,IF(R7<200001,2,IF(R7<500001,3,IF(R7<1000001,4,5))))) -> 1 | V7: 1 | Z7: =MAX(U7:Y7) -> 1 | AA7: =IF(Z7=1,VLOOKUP(T7,$AH$3:$AI$7,2,FALSE),IF(Z7=2,VLOOKUP(T7,$AH$8:$AI$12,2, FALSE),IF(Z7=3,VLOOKUP(T7,$AH$13:$AI$17,2,FALSE),IF(Z7=4,VLOOKUP(T7,$AH$18:$AI$22,2,FALSE),IF(Z7=5,VLOOKUP(T7,$AH$23:$AI$27,2,FALSE),""))))) -> Bajo | AB7: =IF(T7="1-Raro",IF(Z7=1,1,IF(Z7=2,3,IF(Z7=3,6,IF(Z7=4,10,15)))),IF(T7="2-Improbable",IF(Z7=1,2,IF(Z7=2,5,IF(Z7=3,9,IF(Z7=4,14,19)))),IF(T7="3-Posible",IF(Z7=1,4,IF(Z7=2,8,IF(Z7=3,13,IF(Z7=4,18,21)))),IF(T7="4-Probable",IF(Z7=1,7,IF(Z7=2,12,IF(Z7=3,17,IF(Z7=4,22,23)))),IF(T7="5-Casi Seguro",IF(Z7=1,11,IF(Z7=2,16,IF(Z7=3,20,IF(Z7=4,24,25))))))))) -> 7 | AC7: =((VLOOKUP(T7,$AH$3:$AJ$7,3,FALSE)*SQRT(U7^2+V7^2+W7^2+X7^2+Y7^2))/(5*SQRT((5)*5^2))) -> 0.10119289 | AH7: 1-Raro | AI7: Bajo | AJ7: 1
A8: 2100 Chancado Primario & Acopio Mineral Mina | B8: 2110 Estación de chancador primario | C8: Chancador de mandíbula | D8: 2110CR0001 | E8: Chancador de mandíbula | F8: Trituración de mineral proveniente de tolva room 2110BN0001 y ser transferido posteriormente a correa 2110CV0001 | G8: Parada de chancador por presencia de inchancables | H8: Afectación a producción, Parada de chancador y alimentación Stock pile, Retiro de inchancables | I8: 1 | J8: 1 | K8: =+IF(I8="","",IF((I8-J8)>0,"Si","No")) -> No | L8: Ninguna | M8: 1 | N8: 1 | O8: 70 | P8: 10 | Q8: =+IF(M8="","",(IF(((M8*24)-P8)<0,0,(M8*24)-P8)*N8)) -> 14 | R8: =+(IF(((M8*24)-P8)<0,0,((M8*24)-P8)*'Estimación de pérdidas'!$F$72))*N8 -> 807493.05 | S8: No | T8: 4-Probable | U8: =+IF(R8="","",IF(R8<50001,1,IF(R8<200001,2,IF(R8<500001,3,IF(R8<1000001,4,5))))) -> 4 | V8: 1 | Z8: =MAX(U8:Y8) -> 4 | AA8: =IF(Z8=1,VLOOKUP(T8,$AH$3:$AI$7,2,FALSE),IF(Z8=2,VLOOKUP(T8,$AH$8:$AI$12,2, FALSE),IF(Z8=3,VLOOKUP(T8,$AH$13:$AI$17,2,FALSE),IF(Z8=4,VLOOKUP(T8,$AH$18:$AI$22,2,FALSE),IF(Z8=5,VLOOKUP(T8,$AH$23:$AI$27,2,FALSE),""))))) -> Alto | AB8: =IF(T8="1-Raro",IF(Z8=1,1,IF(Z8=2,3,IF(Z8=3,6,IF(Z8=4,10,15)))),IF(T8="2-Improbable",IF(Z8=1,2,IF(Z8=2,5,IF(Z8=3,9,IF(Z8=4,14,19)))),IF(T8="3-Posible",IF(Z8=1,4,IF(Z8=2,8,IF(Z8=3,13,IF(Z8=4,18,21)))),IF(T8="4-Probable",IF(Z8=1,7,IF(Z8=2,12,IF(Z8=3,17,IF(Z8=4,22,23)))),IF(T8="5-Casi Seguro",IF(Z8=1,11,IF(Z8=2,16,IF(Z8=3,20,IF(Z8=4,24,25))))))))) -> 22 | AC8: =((VLOOKUP(T8,$AH$3:$AJ$7,3,FALSE)*SQRT(U8^2+V8^2+W8^2+X8^2+Y8^2))/(5*SQRT((5)*5^2))) -> 0.29502542 | AH8: 5-Casi seguro | AI8: Moderado
A9: 2100 Chancado Primario & Acopio Mineral Mina | B9: 2110 Estación de chancador primario | C9: Rompedor roca | D9: 2110RK0001 | E9: Rompedor roca | F9: Fracturar las rocas de gran tamaño provenientes de Tolva room (2100BN0001) para introducirlas en el chancador de mandíbulas (2110-CR-0001). | G9: Falla cilindro hidráulico de brazo | H9: No afectación a producción, Parada de chancador, Costos por cambio de brazo hidráulico | I9: 1 | J9: 1 | K9: =+IF(I9="","",IF((I9-J9)>0,"Si","No")) -> No | L9: Ninguna | M9: 0.41666667 | N9: 0 | P9: 0 | Q9: =+IF(M9="","",(IF(((M9*24)-P9)<0,0,(M9*24)-P9)*N9)) -> 0 | R9: =+(IF(((M9*24)-P9)<0,0,((M9*24)-P9)*'Estimación de pérdidas'!$F$72))*N9 -> 0 | S9: No | T9: 3-Posible | U9: =+IF(R9="","",IF(R9<50001,1,IF(R9<200001,2,IF(R9<500001,3,IF(R9<1000001,4,5))))) -> 1 | V9: 1 | Z9: =MAX(U9:Y9) -> 1 | AA9: =IF(Z9=1,VLOOKUP(T9,$AH$3:$AI$7,2,FALSE),IF(Z9=2,VLOOKUP(T9,$AH$8:$AI$12,2, FALSE),IF(Z9=3,VLOOKUP(T9,$AH$13:$AI$17,2,FALSE),IF(Z9=4,VLOOKUP(T9,$AH$18:$AI$22,2,FALSE),IF(Z9=5,VLOOKUP(T9,$AH$23:$AI$27,2,FALSE),""))))) -> Bajo | AB9: =IF(T9="1-Raro",IF(Z9=1,1,IF(Z9=2,3,IF(Z9=3,6,IF(Z9=4,10,15)))),IF(T9="2-Improbable",IF(Z9=1,2,IF(Z9=2,5,IF(Z9=3,9,IF(Z9=4,14,19)))),IF(T9="3-Posible",IF(Z9=1,4,IF(Z9=2,8,IF(Z9=3,13,IF(Z9=4,18,21)))),IF(T9="4-Probable",IF(Z9=1,7,IF(Z9=2,12,IF(Z9=3,17,IF(Z9=4,22,23)))),IF(T9="5-Casi Seguro",IF(Z9=1,11,IF(Z9=2,16,IF(Z9=3,20,IF(Z9=4,24,25))))))))) -> 4 | AC9: =((VLOOKUP(T9,$AH$3:$AJ$7,3,FALSE)*SQRT(U9^2+V9^2+W9^2+X9^2+Y9^2))/(5*SQRT((5)*5^2))) -> 0.075894664 | AH9: 4-Probable | AI9: Moderado
A10: 2100 Chancado Primario & Acopio Mineral Mina | B10: 2110 Estación de chancador primario | C10: Correa descarga Chancador | D10: 2110CV0001 | E10: Correa descarga Chancador | F10: Recepcionar la descarga de producto de chancado (P80: 150 mm) a través del chute de transferencia (2110-CH-0004). Esta correa está equipada con un electroimán (2110-MA-0001) para retirar las piezas metálicas magnéticas que vienen con el mineral. | G10: Rotura correa transportadora (64 m) | H10: Afectación a producción, Parada de Chancador, Parada Molino SAG, Costos por cambio de correa | I10: 1 | J10: 1 | K10: =+IF(I10="","",IF((I10-J10)>0,"Si","No")) -> No | L10: Ninguna | M10: 1.5 | N10: 1 | O10: 70 | P10: 10 | Q10: =+IF(M10="","",(IF(((M10*24)-P10)<0,0,(M10*24)-P10)*N10)) -> 26 | R10: =+(IF(((M10*24)-P10)<0,0,((M10*24)-P10)*'Estimación de pérdidas'!$F$72))*N10 -> 1499629.9 | S10: No | T10: 3-Posible | U10: =+IF(R10="","",IF(R10<50001,1,IF(R10<200001,2,IF(R10<500001,3,IF(R10<1000001,4,5))))) -> 5 | V10: 1 | Z10: =MAX(U10:Y10) -> 5 | AA10: =IF(Z10=1,VLOOKUP(T10,$AH$3:$AI$7,2,FALSE),IF(Z10=2,VLOOKUP(T10,$AH$8:$AI$12,2, FALSE),IF(Z10=3,VLOOKUP(T10,$AH$13:$AI$17,2,FALSE),IF(Z10=4,VLOOKUP(T10,$AH$18:$AI$22,2,FALSE),IF(Z10=5,VLOOKUP(T10,$AH$23:$AI$27,2,FALSE),""))))) -> Alto | AB10: =IF(T10="1-Raro",IF(Z10=1,1,IF(Z10=2,3,IF(Z10=3,6,IF(Z10=4,10,15)))),IF(T10="2-Improbable",IF(Z10=1,2,IF(Z10=2,5,IF(Z10=3,9,IF(Z10=4,14,19)))),IF(T10="3-Posible",IF(Z10=1,4,IF(Z10=2,8,IF(Z10=3,13,IF(Z10=4,18,21)))),IF(T10="4-Probable",IF(Z10=1,7,IF(Z10=2,12,IF(Z10=3,17,IF(Z10=4,22,23)))),IF(T10="5-Casi Seguro",IF(Z10=1,11,IF(Z10=2,16,IF(Z10=3,20,IF(Z10=4,24,25))))))))) -> 21 | AC10: =((VLOOKUP(T10,$AH$3:$AJ$7,3,FALSE)*SQRT(U10^2+V10^2+W10^2+X10^2+Y10^2))/(5*SQRT((5)*5^2))) -> 0.2736421 | AH10: 3-Posible | AI10: Moderado
A11: 2100 Chancado Primario & Acopio Mineral Mina | B11: 2120 Alimentación acopio de gruesos | C11: Correa alimentación acopio | D11: 2120CV0002 | E11: Correa alimentación acopio | F11: Recibir el producto descargado de correa descarga de chancador 2120-CV-0001 y alimentar el acopio de mineral a través de chute 2120-CH-0006. La correa cuenta con un pesó metro (2120-SC-0001), el cual permite la medición y el registro de la masa de alimentación de mineral | G11: Rotura correa transportadora (295 m) | H11: Afectación a producción, Parada de Chancador, Parada Molino SAG, Costos por cambio de correa | I11: 1 | J11: 1 | K11: =+IF(I11="","",IF((I11-J11)>0,"Si","No")) -> No | L11: Ninguna | M11: 3 | N11: 1 | O11: 70 | P11: 10 | Q11: =+IF(M11="","",(IF(((M11*24)-P11)<0,0,(M11*24)-P11)*N11)) -> 62 | R11: =+(IF(((M11*24)-P11)<0,0,((M11*24)-P11)*'Estimación de pérdidas'!$F$72))*N11 -> 3576040.6 | S11: No | T11: 2-Improbable | U11: =+IF(R11="","",IF(R11<50001,1,IF(R11<200001,2,IF(R11<500001,3,IF(R11<1000001,4,5))))) -> 5 | V11: 2 | Z11: =MAX(U11:Y11) -> 5 | AA11: =IF(Z11=1,VLOOKUP(T11,$AH$3:$AI$7,2,FALSE),IF(Z11=2,VLOOKUP(T11,$AH$8:$AI$12,2, FALSE),IF(Z11=3,VLOOKUP(T11,$AH$13:$AI$17,2,FALSE),IF(Z11=4,VLOOKUP(T11,$AH$18:$AI$22,2,FALSE),IF(Z11=5,VLOOKUP(T11,$AH$23:$AI$27,2,FALSE),""))))) -> Alto | AB11: =IF(T11="1-Raro",IF(Z11=1,1,IF(Z11=2,3,IF(Z11=3,6,IF(Z11=4,10,15)))),IF(T11="2-Improbable",IF(Z11=1,2,IF(Z11=2,5,IF(Z11=3,9,IF(Z11=4,14,19)))),IF(T11="3-Posible",IF(Z11=1,4,IF(Z11=2,8,IF(Z11=3,13,IF(Z11=4,18,21)))),IF(T11="4-Probable",IF(Z11=1,7,IF(Z11=2,12,IF(Z11=3,17,IF(Z11=4,22,23)))),IF(T11="5-Casi Seguro",IF(Z11=1,11,IF(Z11=2,16,IF(Z11=3,20,IF(Z11=4,24,25))))))))) -> 19 | AC11: =((VLOOKUP(T11,$AH$3:$AJ$7,3,FALSE)*SQRT(U11^2+V11^2+W11^2+X11^2+Y11^2))/(5*SQRT((5)*5^2))) -> 0.19266551 | AH11: 2-Improbable | AI11: Bajo
A12: 2100 Chancado Primario & Acopio Mineral Mina | B12: 2110 Estación de chancador primario | C12: Sistema supresión de polvo | D12: 2110DT0001 | E12: Sistema supresión polvo | F12: Producir neblina a partir de aire comprimido inyectado a las boquillas de aspersión de agua encapsulando el polvo generado en Tolva Room, en chancador primario y su respectiva correa de descarga | G12: Rotura cámara de niebla | H12: Área contaminada de polvo sin efectos posteriores en salud de personas, No afectación en producción, Cambio cámara de niebla | I12: 1 | J12: 1 | K12: =+IF(I12="","",IF((I12-J12)>0,"Si","No")) -> No | L12: Ninguna | M12: 0.25 | N12: 0 | O12: 70 | P12: 10 | Q12: =+IF(M12="","",(IF(((M12*24)-P12)<0,0,(M12*24)-P12)*N12)) -> 0 | R12: =+(IF(((M12*24)-P12)<0,0,((M12*24)-P12)*'Estimación de pérdidas'!$F$72))*N12 -> 0 | S12: No | T12: 3-Posible | U12: =+IF(R12="","",IF(R12<50001,1,IF(R12<200001,2,IF(R12<500001,3,IF(R12<1000001,4,5))))) -> 1 | V12: 1 | Z12: =MAX(U12:Y12) -> 1 | AA12: =IF(Z12=1,VLOOKUP(T12,$AH$3:$AI$7,2,FALSE),IF(Z12=2,VLOOKUP(T12,$AH$8:$AI$12,2, FALSE),IF(Z12=3,VLOOKUP(T12,$AH$13:$AI$17,2,FALSE),IF(Z12=4,VLOOKUP(T12,$AH$18:$AI$22,2,FALSE),IF(Z12=5,VLOOKUP(T12,$AH$23:$AI$27,2,FALSE),""))))) -> Bajo | AB12: =IF(T12="1-Raro",IF(Z12=1,1,IF(Z12=2,3,IF(Z12=3,6,IF(Z12=4,10,15)))),IF(T12="2-Improbable",IF(Z12=1,2,IF(Z12=2,5,IF(Z12=3,9,IF(Z12=4,14,19)))),IF(T12="3-Posible",IF(Z12=1,4,IF(Z12=2,8,IF(Z12=3,13,IF(Z12=4,18,21)))),IF(T12="4-Probable",IF(Z12=1,7,IF(Z12=2,12,IF(Z12=3,17,IF(Z12=4,22,23)))),IF(T12="5-Casi Seguro",IF(Z12=1,11,IF(Z12=2,16,IF(Z12=3,20,IF(Z12=4,24,25))))))))) -> 4 | AC12: =((VLOOKUP(T12,$AH$3:$AJ$7,3,FALSE)*SQRT(U12^2+V12^2+W12^2+X12^2+Y12^2))/(5*SQRT((5)*5^2))) -> 0.075894664 | AH12: 1-Raro | AI12: Bajo
A13: 2100 Chancado Primario & Acopio Mineral Mina | B13: 2110 Estación de chancador primario | C13: Sistema supresión de polvo | D13: 2110DT0002 | E13: Sistema supresión polvo | F13: Producir neblina a partir de aire comprimido inyectado a las boquillas de aspersión de agua encapsulando el polvo generado en correa alimentación acopio | G13: Rotura cámara de niebla | H13: Área contaminada de polvo sin efectos posteriores en salud de personas, No afectación en producción, Cambio cámara de niebla | I13: 1 | J13: 1 | K13: =+IF(I13="","",IF((I13-J13)>0,"Si","No")) -> No | L13: Ninguna | M13: 0.25 | N13: 0 | O13: 70 | P13: 10 | Q13: =+IF(M13="","",(IF(((M13*24)-P13)<0,0,(M13*24)-P13)*N13)) -> 0 | R13: =+(IF(((M13*24)-P13)<0,0,((M13*24)-P13)*'Estimación de pérdidas'!$F$72))*N13 -> 0 | S13: No | T13: 3-Posible | U13: =+IF(R13="","",IF(R13<50001,1,IF(R13<200001,2,IF(R13<500001,3,IF(R13<1000001,4,5))))) -> 1 | V13: 1 | Z13: =MAX(U13:Y13) -> 1 | AA13: =IF(Z13=1,VLOOKUP(T13,$AH$3:$AI$7,2,FALSE),IF(Z13=2,VLOOKUP(T13,$AH$8:$AI$12,2, FALSE),IF(Z13=3,VLOOKUP(T13,$AH$13:$AI$17,2,FALSE),IF(Z13=4,VLOOKUP(T13,$AH$18:$AI$22,2,FALSE),IF(Z13=5,VLOOKUP(T13,$AH$23:$AI$27,2,FALSE),""))))) -> Bajo | AB13: =IF(T13="1-Raro",IF(Z13=1,1,IF(Z13=2,3,IF(Z13=3,6,IF(Z13=4,10,15)))),IF(T13="2-Improbable",IF(Z13=1,2,IF(Z13=2,5,IF(Z13=3,9,IF(Z13=4,14,19)))),IF(T13="3-Posible",IF(Z13=1,4,IF(Z13=2,8,IF(Z13=3,13,IF(Z13=4,18,21)))),IF(T13="4-Probable",IF(Z13=1,7,IF(Z13=2,12,IF(Z13=3,17,IF(Z13=4,22,23)))),IF(T13="5-Casi Seguro",IF(Z13=1,11,IF(Z13=2,16,IF(Z13=3,20,IF(Z13=4,24,25))))))))) -> 4 | AC13: =((VLOOKUP(T13,$AH$3:$AJ$7,3,FALSE)*SQRT(U13^2+V13^2+W13^2+X13^2+Y13^2))/(5*SQRT((5)*5^2))) -> 0.075894664 | AH13: 5-Casi seguro | AI13: Alto
A14: 2100 Chancado Primario & Acopio Mineral Mina | B14: 2110 Estación de chancador primario | C14: Tolva descarga electroimán | D14: 2110BN0002 | E14: Tolva descarga electroimán | F14: Almacenar la descarga de electroimán de correa descarga de chancador 2110CV0001 | G14: Rotura en paredes de tolva | H14: No afectación a producción, Costos reparación de tolva | I14: 1 | J14: 1 | K14: =+IF(I14="","",IF((I14-J14)>0,"Si","No")) -> No | L14: Ninguna | M14: 0.33333333 | N14: 0 | O14: 70 | P14: 10 | Q14: =+IF(M14="","",(IF(((M14*24)-P14)<0,0,(M14*24)-P14)*N14)) -> 0 | R14: =+(IF(((M14*24)-P14)<0,0,((M14*24)-P14)*'Estimación de pérdidas'!$F$72))*N14 -> 0 | S14: No | T14: 2-Improbable | U14: =+IF(R14="","",IF(R14<50001,1,IF(R14<200001,2,IF(R14<500001,3,IF(R14<1000001,4,5))))) -> 1 | V14: 1 | Z14: =MAX(U14:Y14) -> 1 | AA14: =IF(Z14=1,VLOOKUP(T14,$AH$3:$AI$7,2,FALSE),IF(Z14=2,VLOOKUP(T14,$AH$8:$AI$12,2, FALSE),IF(Z14=3,VLOOKUP(T14,$AH$13:$AI$17,2,FALSE),IF(Z14=4,VLOOKUP(T14,$AH$18:$AI$22,2,FALSE),IF(Z14=5,VLOOKUP(T14,$AH$23:$AI$27,2,FALSE),""))))) -> Bajo | AB14: =IF(T14="1-Raro",IF(Z14=1,1,IF(Z14=2,3,IF(Z14=3,6,IF(Z14=4,10,15)))),IF(T14="2-Improbable",IF(Z14=1,2,IF(Z14=2,5,IF(Z14=3,9,IF(Z14=4,14,19)))),IF(T14="3-Posible",IF(Z14=1,4,IF(Z14=2,8,IF(Z14=3,13,IF(Z14=4,18,21)))),IF(T14="4-Probable",IF(Z14=1,7,IF(Z14=2,12,IF(Z14=3,17,IF(Z14=4,22,23)))),IF(T14="5-Casi Seguro",IF(Z14=1,11,IF(Z14=2,16,IF(Z14=3,20,IF(Z14=4,24,25))))))))) -> 2 | AC14: =((VLOOKUP(T14,$AH$3:$AJ$7,3,FALSE)*SQRT(U14^2+V14^2+W14^2+X14^2+Y14^2))/(5*SQRT((5)*5^2))) -> 0.050596443 | AH14: 4-Probable | AI14: Moderado
A15: 2100 Chancado Primario & Acopio Mineral Mina | B15: 2110 Estación de chancador primario | C15: Tecle torre de transferencia | D15: 2110HT0003 | E15: Tecle descarga chancador | F15: Izar y desplazar cargas en el área de chancado primario | G15: Falla de cableado / cadena | H15: No afectación a operaciones, Cambiar el tecle | I15: 1 | J15: 1 | K15: =+IF(I15="","",IF((I15-J15)>0,"Si","No")) -> No | L15: Ninguna | M15: 0.33333333 | N15: 0 | P15: 0 | Q15: =+IF(M15="","",(IF(((M15*24)-P15)<0,0,(M15*24)-P15)*N15)) -> 0 | R15: =+(IF(((M15*24)-P15)<0,0,((M15*24)-P15)*'Estimación de pérdidas'!$F$72))*N15 -> 0 | S15: No | T15: 3-Posible | U15: =+IF(R15="","",IF(R15<50001,1,IF(R15<200001,2,IF(R15<500001,3,IF(R15<1000001,4,5))))) -> 1 | V15: 1 | Z15: =MAX(U15:Y15) -> 1 | AA15: =IF(Z15=1,VLOOKUP(T15,$AH$3:$AI$7,2,FALSE),IF(Z15=2,VLOOKUP(T15,$AH$8:$AI$12,2, FALSE),IF(Z15=3,VLOOKUP(T15,$AH$13:$AI$17,2,FALSE),IF(Z15=4,VLOOKUP(T15,$AH$18:$AI$22,2,FALSE),IF(Z15=5,VLOOKUP(T15,$AH$23:$AI$27,2,FALSE),""))))) -> Bajo | AB15: =IF(T15="1-Raro",IF(Z15=1,1,IF(Z15=2,3,IF(Z15=3,6,IF(Z15=4,10,15)))),IF(T15="2-Improbable",IF(Z15=1,2,IF(Z15=2,5,IF(Z15=3,9,IF(Z15=4,14,19)))),IF(T15="3-Posible",IF(Z15=1,4,IF(Z15=2,8,IF(Z15=3,13,IF(Z15=4,18,21)))),IF(T15="4-Probable",IF(Z15=1,7,IF(Z15=2,12,IF(Z15=3,17,IF(Z15=4,22,23)))),IF(T15="5-Casi Seguro",IF(Z15=1,11,IF(Z15=2,16,IF(Z15=3,20,IF(Z15=4,24,25))))))))) -> 4 | AC15: =((VLOOKUP(T15,$AH$3:$AJ$7,3,FALSE)*SQRT(U15^2+V15^2+W15^2+X15^2+Y15^2))/(5*SQRT((5)*5^2))) -> 0.075894664 | AH15: 3-Posible | AI15: Moderado
A16: 2100 Chancado Primario & Acopio Mineral Mina | B16: 2110 Estación de chancador primario | C16: Carro electroimán | D16: 2110HT0002 | E16: Carro electroimán | F16: Desplazar material recuperado a tolva electroimán de correa descarga de chancador 2110CV0001 | G16: Falla de cableado / cadena | H16: No afectación a operaciones, Cambiar el tecle | I16: 1 | J16: 1 | K16: =+IF(I16="","",IF((I16-J16)>0,"Si","No")) -> No | L16: Ninguna | M16: 0.33333333 | N16: 0 | P16: 0 | Q16: =+IF(M16="","",(IF(((M16*24)-P16)<0,0,(M16*24)-P16)*N16)) -> 0 | R16: =+(IF(((M16*24)-P16)<0,0,((M16*24)-P16)*'Estimación de pérdidas'!$F$72))*N16 -> 0 | S16: No | T16: 3-Posible | U16: =+IF(R16="","",IF(R16<50001,1,IF(R16<200001,2,IF(R16<500001,3,IF(R16<1000001,4,5))))) -> 1 | V16: 1 | Z16: =MAX(U16:Y16) -> 1 | AA16: =IF(Z16=1,VLOOKUP(T16,$AH$3:$AI$7,2,FALSE),IF(Z16=2,VLOOKUP(T16,$AH$8:$AI$12,2, FALSE),IF(Z16=3,VLOOKUP(T16,$AH$13:$AI$17,2,FALSE),IF(Z16=4,VLOOKUP(T16,$AH$18:$AI$22,2,FALSE),IF(Z16=5,VLOOKUP(T16,$AH$23:$AI$27,2,FALSE),""))))) -> Bajo | AB16: =IF(T16="1-Raro",IF(Z16=1,1,IF(Z16=2,3,IF(Z16=3,6,IF(Z16=4,10,15)))),IF(T16="2-Improbable",IF(Z16=1,2,IF(Z16=2,5,IF(Z16=3,9,IF(Z16=4,14,19)))),IF(T16="3-Posible",IF(Z16=1,4,IF(Z16=2,8,IF(Z16=3,13,IF(Z16=4,18,21)))),IF(T16="4-Probable",IF(Z16=1,7,IF(Z16=2,12,IF(Z16=3,17,IF(Z16=4,22,23)))),IF(T16="5-Casi Seguro",IF(Z16=1,11,IF(Z16=2,16,IF(Z16=3,20,IF(Z16=4,24,25))))))))) -> 4 | AC16: =((VLOOKUP(T16,$AH$3:$AJ$7,3,FALSE)*SQRT(U16^2+V16^2+W16^2+X16^2+Y16^2))/(5*SQRT((5)*5^2))) -> 0.075894664 | AH16: 2-Improbable | AI16: Moderado
A17: 2100 Chancado Primario & Acopio Mineral Mina | B17: 2110 Estación de chancador primario | C17: Chute descarga Chancador | D17: 2110CH0004 | E17: Chute descarga Chancador | F17: Almacenar la descarga de chancador 2110CR0001 y transferir a la correa descarga de chancador 2110CV0001 | G17: Rotura de chute | H17: No afectación a producción, Parada de chancador de mandíbula, Costos por reparación de chute | I17: 1 | J17: 1 | K17: =+IF(I17="","",IF((I17-J17)>0,"Si","No")) -> No | L17: Ninguna | M17: 0.41666667 | N17: 1 | O17: 70 | P17: 10 | Q17: =+IF(M17="","",(IF(((M17*24)-P17)<0,0,(M17*24)-P17)*N17)) -> 0 | R17: =+(IF(((M17*24)-P17)<0,0,((M17*24)-P17)*'Estimación de pérdidas'!$F$72))*N17 -> 0 | S17: No | T17: 3-Posible | U17: =+IF(R17="","",IF(R17<50001,1,IF(R17<200001,2,IF(R17<500001,3,IF(R17<1000001,4,5))))) -> 1 | V17: 1 | Z17: =MAX(U17:Y17) -> 1 | AA17: =IF(Z17=1,VLOOKUP(T17,$AH$3:$AI$7,2,FALSE),IF(Z17=2,VLOOKUP(T17,$AH$8:$AI$12,2, FALSE),IF(Z17=3,VLOOKUP(T17,$AH$13:$AI$17,2,FALSE),IF(Z17=4,VLOOKUP(T17,$AH$18:$AI$22,2,FALSE),IF(Z17=5,VLOOKUP(T17,$AH$23:$AI$27,2,FALSE),""))))) -> Bajo | AB17: =IF(T17="1-Raro",IF(Z17=1,1,IF(Z17=2,3,IF(Z17=3,6,IF(Z17=4,10,15)))),IF(T17="2-Improbable",IF(Z17=1,2,IF(Z17=2,5,IF(Z17=3,9,IF(Z17=4,14,19)))),IF(T17="3-Posible",IF(Z17=1,4,IF(Z17=2,8,IF(Z17=3,13,IF(Z17=4,18,21)))),IF(T17="4-Probable",IF(Z17=1,7,IF(Z17=2,12,IF(Z17=3,17,IF(Z17=4,22,23)))),IF(T17="5-Casi Seguro",IF(Z17=1,11,IF(Z17=2,16,IF(Z17=3,20,IF(Z17=4,24,25))))))))) -> 4 | AC17: =((VLOOKUP(T17,$AH$3:$AJ$7,3,FALSE)*SQRT(U17^2+V17^2+W17^2+X17^2+Y17^2))/(5*SQRT((5)*5^2))) -> 0.075894664 | AH17: 1-Raro | AI17: Bajo
A18: 2100 Chancado Primario & Acopio Mineral Mina | B18: 2110 Estación de chancador primario | C18: Chute descarga correa | D18: 2110CH0005 | E18: Chute descarga correa | F18: Recepcionar el producto descargado de correa descarga de chancador 2120-CV-0001 y alimentar la correa alimentación de acopio 2110-CV-0002 | G18: Rotura de chute | H18: No afectación a producción, Parada de chancador de mandíbula, Detención de correa, Costos por reparación de chute | I18: 1 | J18: 1 | K18: =+IF(I18="","",IF((I18-J18)>0,"Si","No")) -> No | L18: Ninguna | M18: 0.41666667 | N18: 1 | O18: 70 | P18: 10 | Q18: =+IF(M18="","",(IF(((M18*24)-P18)<0,0,(M18*24)-P18)*N18)) -> 0 | R18: =+(IF(((M18*24)-P18)<0,0,((M18*24)-P18)*'Estimación de pérdidas'!$F$72))*N18 -> 0 | S18: No | T18: 3-Posible | U18: =+IF(R18="","",IF(R18<50001,1,IF(R18<200001,2,IF(R18<500001,3,IF(R18<1000001,4,5))))) -> 1 | V18: 1 | Z18: =MAX(U18:Y18) -> 1 | AA18: =IF(Z18=1,VLOOKUP(T18,$AH$3:$AI$7,2,FALSE),IF(Z18=2,VLOOKUP(T18,$AH$8:$AI$12,2, FALSE),IF(Z18=3,VLOOKUP(T18,$AH$13:$AI$17,2,FALSE),IF(Z18=4,VLOOKUP(T18,$AH$18:$AI$22,2,FALSE),IF(Z18=5,VLOOKUP(T18,$AH$23:$AI$27,2,FALSE),""))))) -> Bajo | AB18: =IF(T18="1-Raro",IF(Z18=1,1,IF(Z18=2,3,IF(Z18=3,6,IF(Z18=4,10,15)))),IF(T18="2-Improbable",IF(Z18=1,2,IF(Z18=2,5,IF(Z18=3,9,IF(Z18=4,14,19)))),IF(T18="3-Posible",IF(Z18=1,4,IF(Z18=2,8,IF(Z18=3,13,IF(Z18=4,18,21)))),IF(T18="4-Probable",IF(Z18=1,7,IF(Z18=2,12,IF(Z18=3,17,IF(Z18=4,22,23)))),IF(T18="5-Casi Seguro",IF(Z18=1,11,IF(Z18=2,16,IF(Z18=3,20,IF(Z18=4,24,25))))))))) -> 4 | AC18: =((VLOOKUP(T18,$AH$3:$AJ$7,3,FALSE)*SQRT(U18^2+V18^2+W18^2+X18^2+Y18^2))/(5*SQRT((5)*5^2))) -> 0.075894664 | AH18: 5-Casi seguro | AI18: Alto
A19: 2100 Chancado Primario & Acopio Mineral Mina | B19: 2110 Estación de chancador primario | C19: Puente grúa Chancador | D19: 2110CN0003 | E19: Puente grúa chancador | F19: Izar y desplazar cargas en el área de chancado primario | G19: Falla de cable | H19: Fatalidad o incapacidad permanente a una persona, No afectación a operaciones, Cambio de cable | I19: 1 | J19: 1 | K19: =+IF(I19="","",IF((I19-J19)>0,"Si","No")) -> No | L19: Ninguna | M19: 0.5 | N19: 0 | P19: 0 | Q19: =+IF(M19="","",(IF(((M19*24)-P19)<0,0,(M19*24)-P19)*N19)) -> 0 | R19: =+(IF(((M19*24)-P19)<0,0,((M19*24)-P19)*'Estimación de pérdidas'!$F$72))*N19 -> 0 | S19: No | T19: 2-Improbable | U19: =+IF(R19="","",IF(R19<50001,1,IF(R19<200001,2,IF(R19<500001,3,IF(R19<1000001,4,5))))) -> 1 | V19: 2 | W19: 4 | Z19: =MAX(U19:Y19) -> 4 | AA19: =IF(Z19=1,VLOOKUP(T19,$AH$3:$AI$7,2,FALSE),IF(Z19=2,VLOOKUP(T19,$AH$8:$AI$12,2, FALSE),IF(Z19=3,VLOOKUP(T19,$AH$13:$AI$17,2,FALSE),IF(Z19=4,VLOOKUP(T19,$AH$18:$AI$22,2,FALSE),IF(Z19=5,VLOOKUP(T19,$AH$23:$AI$27,2,FALSE),""))))) -> Moderado | AB19: =IF(T19="1-Raro",IF(Z19=1,1,IF(Z19=2,3,IF(Z19=3,6,IF(Z19=4,10,15)))),IF(T19="2-Improbable",IF(Z19=1,2,IF(Z19=2,5,IF(Z19=3,9,IF(Z19=4,14,19)))),IF(T19="3-Posible",IF(Z19=1,4,IF(Z19=2,8,IF(Z19=3,13,IF(Z19=4,18,21)))),IF(T19="4-Probable",IF(Z19=1,7,IF(Z19=2,12,IF(Z19=3,17,IF(Z19=4,22,23)))),IF(T19="5-Casi Seguro",IF(Z19=1,11,IF(Z19=2,16,IF(Z19=3,20,IF(Z19=4,24,25))))))))) -> 14 | AC19: =((VLOOKUP(T19,$AH$3:$AJ$7,3,FALSE)*SQRT(U19^2+V19^2+W19^2+X19^2+Y19^2))/(5*SQRT((5)*5^2))) -> 0.16395121 | AH19: 4-Probable | AI19: Alto
A20: 2100 Chancado Primario & Acopio Mineral Mina | B20: 2110 Estación de chancador primario | C20: Puente grúa tolva ROM | D20: 2110CN0022 | E20: Puente grúa tolva ROM | F20: Izaje y traslado de cargas en tolva room 2110BN0001 | G20: Falla de cable | H20: Fatalidad o incapacidad permanente a una persona, No afectación a operaciones, Cambio de cable | I20: 1 | J20: 1 | K20: =+IF(I20="","",IF((I20-J20)>0,"Si","No")) -> No | L20: Ninguna | M20: 0.5 | N20: 0 | P20: 0 | Q20: =+IF(M20="","",(IF(((M20*24)-P20)<0,0,(M20*24)-P20)*N20)) -> 0 | R20: =+(IF(((M20*24)-P20)<0,0,((M20*24)-P20)*'Estimación de pérdidas'!$F$72))*N20 -> 0 | S20: No | T20: 2-Improbable | U20: =+IF(R20="","",IF(R20<50001,1,IF(R20<200001,2,IF(R20<500001,3,IF(R20<1000001,4,5))))) -> 1 | V20: 2 | W20: 4 | Z20: =MAX(U20:Y20) -> 4 | AA20: =IF(Z20=1,VLOOKUP(T20,$AH$3:$AI$7,2,FALSE),IF(Z20=2,VLOOKUP(T20,$AH$8:$AI$12,2, FALSE),IF(Z20=3,VLOOKUP(T20,$AH$13:$AI$17,2,FALSE),IF(Z20=4,VLOOKUP(T20,$AH$18:$AI$22,2,FALSE),IF(Z20=5,VLOOKUP(T20,$AH$23:$AI$27,2,FALSE),""))))) -> Moderado | AB20: =IF(T20="1-Raro",IF(Z20=1,1,IF(Z20=2,3,IF(Z20=3,6,IF(Z20=4,10,15)))),IF(T20="2-Improbable",IF(Z20=1,2,IF(Z20=2,5,IF(Z20=3,9,IF(Z20=4,14,19)))),IF(T20="3-Posible",IF(Z20=1,4,IF(Z20=2,8,IF(Z20=3,13,IF(Z20=4,18,21)))),IF(T20="4-Probable",IF(Z20=1,7,IF(Z20=2,12,IF(Z20=3,17,IF(Z20=4,22,23)))),IF(T20="5-Casi Seguro",IF(Z20=1,11,IF(Z20=2,16,IF(Z20=3,20,IF(Z20=4,24,25))))))))) -> 14 | AC20: =((VLOOKUP(T20,$AH$3:$AJ$7,3,FALSE)*SQRT(U20^2+V20^2+W20^2+X20^2+Y20^2))/(5*SQRT((5)*5^2))) -> 0.16395121 | AH20: 3-Posible | AI20: Moderado
A21: 2100 Chancado Primario & Acopio Mineral Mina | B21: 2110 Estación de chancador primario | C21: Compresor aire de Chancado | D21: 2110CP0003 | E21: Compresor de aire Chancado | F21: Comprimir el aire, alimentar el acumulador 2110AR0001 y posteriormente alimentar el supresor de polvo 2110DT0001 | G21: Falla de compresor | H21: Área contaminada de polvo sin efectos posteriores en salud de personas, No afectación a producción, Costos por cambio de compresor | I21: 1 | J21: 1 | K21: =+IF(I21="","",IF((I21-J21)>0,"Si","No")) -> No | L21: Ninguna | M21: 1 | N21: 0 | O21: 70 | P21: 10 | Q21: =+IF(M21="","",(IF(((M21*24)-P21)<0,0,(M21*24)-P21)*N21)) -> 0 | R21: =+(IF(((M21*24)-P21)<0,0,((M21*24)-P21)*'Estimación de pérdidas'!$F$72))*N21 -> 0 | S21: No | T21: 2-Improbable | U21: =+IF(R21="","",IF(R21<50001,1,IF(R21<200001,2,IF(R21<500001,3,IF(R21<1000001,4,5))))) -> 1 | V21: 1 | Z21: =MAX(U21:Y21) -> 1 | AA21: =IF(Z21=1,VLOOKUP(T21,$AH$3:$AI$7,2,FALSE),IF(Z21=2,VLOOKUP(T21,$AH$8:$AI$12,2, FALSE),IF(Z21=3,VLOOKUP(T21,$AH$13:$AI$17,2,FALSE),IF(Z21=4,VLOOKUP(T21,$AH$18:$AI$22,2,FALSE),IF(Z21=5,VLOOKUP(T21,$AH$23:$AI$27,2,FALSE),""))))) -> Bajo | AB21: =IF(T21="1-Raro",IF(Z21=1,1,IF(Z21=2,3,IF(Z21=3,6,IF(Z21=4,10,15)))),IF(T21="2-Improbable",IF(Z21=1,2,IF(Z21=2,5,IF(Z21=3,9,IF(Z21=4,14,19)))),IF(T21="3-Posible",IF(Z21=1,4,IF(Z21=2,8,IF(Z21=3,13,IF(Z21=4,18,21)))),IF(T21="4-Probable",IF(Z21=1,7,IF(Z21=2,12,IF(Z21=3,17,IF(Z21=4,22,23)))),IF(T21="5-Casi Seguro",IF(Z21=1,11,IF(Z21=2,16,IF(Z21=3,20,IF(Z21=4,24,25))))))))) -> 2 | AC21: =((VLOOKUP(T21,$AH$3:$AJ$7,3,FALSE)*SQRT(U21^2+V21^2+W21^2+X21^2+Y21^2))/(5*SQRT((5)*5^2))) -> 0.050596443 | AH21: 2-Improbable | AI21: Moderado
A22: 2100 Chancado Primario & Acopio Mineral Mina | B22: 2110 Estación de chancador primario | C22: Tecle chancador primario | D22: 2110HT0042 | E22: Tecle chancador primario | F22: Izar y desplazar cargas en el área de chancado primario | G22: Falla de cableado / cadena | H22: No afectación a operaciones, Cambiar el tecle | I22: 1 | J22: 1 | K22: =+IF(I22="","",IF((I22-J22)>0,"Si","No")) -> No | L22: Ninguna | M22: 0.33333333 | N22: 0 | P22: 0 | Q22: =+IF(M22="","",(IF(((M22*24)-P22)<0,0,(M22*24)-P22)*N22)) -> 0 | R22: =+(IF(((M22*24)-P22)<0,0,((M22*24)-P22)*'Estimación de pérdidas'!$F$72))*N22 -> 0 | S22: No | T22: 3-Posible | U22: =+IF(R22="","",IF(R22<50001,1,IF(R22<200001,2,IF(R22<500001,3,IF(R22<1000001,4,5))))) -> 1 | V22: 1 | Z22: =MAX(U22:Y22) -> 1 | AA22: =IF(Z22=1,VLOOKUP(T22,$AH$3:$AI$7,2,FALSE),IF(Z22=2,VLOOKUP(T22,$AH$8:$AI$12,2, FALSE),IF(Z22=3,VLOOKUP(T22,$AH$13:$AI$17,2,FALSE),IF(Z22=4,VLOOKUP(T22,$AH$18:$AI$22,2,FALSE),IF(Z22=5,VLOOKUP(T22,$AH$23:$AI$27,2,FALSE),""))))) -> Bajo | AB22: =IF(T22="1-Raro",IF(Z22=1,1,IF(Z22=2,3,IF(Z22=3,6,IF(Z22=4,10,15)))),IF(T22="2-Improbable",IF(Z22=1,2,IF(Z22=2,5,IF(Z22=3,9,IF(Z22=4,14,19)))),IF(T22="3-Posible",IF(Z22=1,4,IF(Z22=2,8,IF(Z22=3,13,IF(Z22=4,18,21)))),IF(T22="4-Probable",IF(Z22=1,7,IF(Z22=2,12,IF(Z22=3,17,IF(Z22=4,22,23)))),IF(T22="5-Casi Seguro",IF(Z22=1,11,IF(Z22=2,16,IF(Z22=3,20,IF(Z22=4,24,25))))))))) -> 4 | AC22: =((VLOOKUP(T22,$AH$3:$AJ$7,3,FALSE)*SQRT(U22^2+V22^2+W22^2+X22^2+Y22^2))/(5*SQRT((5)*5^2))) -> 0.075894664 | AH22: 1-Raro | AI22: Moderado
A23: 2100 Chancado Primario & Acopio Mineral Mina | B23: 2110 Estación de chancador primario | C23: Bomba agua supresión de polvo | D23: 2110PU0043 | E23: Bomba agua supresión polvo | F23: Transferir agua de estanque 2110TK0007 a supresor de polvo 2110DT0001 | G23: Falla de bomba hidráulica | H23: Área contaminada de polvo sin efectos posteriores en salud de personas, No afectación en producción, Costo asociados a cambio de bomba | I23: 1 | J23: 1 | K23: =+IF(I23="","",IF((I23-J23)>0,"Si","No")) -> No | L23: Ninguna | M23: 0.25 | N23: 0 | O23: 70 | P23: 10 | Q23: =+IF(M23="","",(IF(((M23*24)-P23)<0,0,(M23*24)-P23)*N23)) -> 0 | R23: =+(IF(((M23*24)-P23)<0,0,((M23*24)-P23)*'Estimación de pérdidas'!$F$72))*N23 -> 0 | S23: No | T23: 4-Probable | U23: =+IF(R23="","",IF(R23<50001,1,IF(R23<200001,2,IF(R23<500001,3,IF(R23<1000001,4,5))))) -> 1 | V23: 1 | Z23: =MAX(U23:Y23) -> 1 | AA23: =IF(Z23=1,VLOOKUP(T23,$AH$3:$AI$7,2,FALSE),IF(Z23=2,VLOOKUP(T23,$AH$8:$AI$12,2, FALSE),IF(Z23=3,VLOOKUP(T23,$AH$13:$AI$17,2,FALSE),IF(Z23=4,VLOOKUP(T23,$AH$18:$AI$22,2,FALSE),IF(Z23=5,VLOOKUP(T23,$AH$23:$AI$27,2,FALSE),""))))) -> Bajo | AB23: =IF(T23="1-Raro",IF(Z23=1,1,IF(Z23=2,3,IF(Z23=3,6,IF(Z23=4,10,15)))),IF(T23="2-Improbable",IF(Z23=1,2,IF(Z23=2,5,IF(Z23=3,9,IF(Z23=4,14,19)))),IF(T23="3-Posible",IF(Z23=1,4,IF(Z23=2,8,IF(Z23=3,13,IF(Z23=4,18,21)))),IF(T23="4-Probable",IF(Z23=1,7,IF(Z23=2,12,IF(Z23=3,17,IF(Z23=4,22,23)))),IF(T23="5-Casi Seguro",IF(Z23=1,11,IF(Z23=2,16,IF(Z23=3,20,IF(Z23=4,24,25))))))))) -> 7 | AC23: =((VLOOKUP(T23,$AH$3:$AJ$7,3,FALSE)*SQRT(U23^2+V23^2+W23^2+X23^2+Y23^2))/(5*SQRT((5)*5^2))) -> 0.10119289 | AH23: 5-Casi seguro | AI23: Alto
A24: 2100 Chancado Primario & Acopio Mineral Mina | B24: 2110 Estación de chancador primario | C24: Estanque de agua fresca Chancado | D24: 2110TK0007 | E24: Estanque agua fresca chancador | F24: Almacenar agua fresca proveniente de 4100TK0042 para alimentar a través de 2110PU0043 el supresor de polvo 2110DT0001 | G24: Falla de contención de tanque | H24: No afectación a producción, Reparación de estructura de estanque | I24: 1 | J24: 1 | K24: =+IF(I24="","",IF((I24-J24)>0,"Si","No")) -> No | L24: Ninguna | M24: 1 | N24: 0 | O24: 70 | P24: 10 | Q24: =+IF(M24="","",(IF(((M24*24)-P24)<0,0,(M24*24)-P24)*N24)) -> 0 | R24: =+(IF(((M24*24)-P24)<0,0,((M24*24)-P24)*'Estimación de pérdidas'!$F$72))*N24 -> 0 | S24: No | T24: 2-Improbable | U24: =+IF(R24="","",IF(R24<50001,1,IF(R24<200001,2,IF(R24<500001,3,IF(R24<1000001,4,5))))) -> 1 | V24: 1 | Z24: =MAX(U24:Y24) -> 1 | AA24: =IF(Z24=1,VLOOKUP(T24,$AH$3:$AI$7,2,FALSE),IF(Z24=2,VLOOKUP(T24,$AH$8:$AI$12,2, FALSE),IF(Z24=3,VLOOKUP(T24,$AH$13:$AI$17,2,FALSE),IF(Z24=4,VLOOKUP(T24,$AH$18:$AI$22,2,FALSE),IF(Z24=5,VLOOKUP(T24,$AH$23:$AI$27,2,FALSE),""))))) -> Bajo | AB24: =IF(T24="1-Raro",IF(Z24=1,1,IF(Z24=2,3,IF(Z24=3,6,IF(Z24=4,10,15)))),IF(T24="2-Improbable",IF(Z24=1,2,IF(Z24=2,5,IF(Z24=3,9,IF(Z24=4,14,19)))),IF(T24="3-Posible",IF(Z24=1,4,IF(Z24=2,8,IF(Z24=3,13,IF(Z24=4,18,21)))),IF(T24="4-Probable",IF(Z24=1,7,IF(Z24=2,12,IF(Z24=3,17,IF(Z24=4,22,23)))),IF(T24="5-Casi Seguro",IF(Z24=1,11,IF(Z24=2,16,IF(Z24=3,20,IF(Z24=4,24,25))))))))) -> 2 | AC24: =((VLOOKUP(T24,$AH$3:$AJ$7,3,FALSE)*SQRT(U24^2+V24^2+W24^2+X24^2+Y24^2))/(5*SQRT((5)*5^2))) -> 0.050596443 | AH24: 4-Probable | AI24: Alto
A25: 2100 Chancado Primario & Acopio Mineral Mina | B25: 2120 Alimentación acopio de gruesos | C25: Chute alimentación acopio | D25: 2120CH0006 | E25: Chute alimentación acopio | F25: Alimentar el acopio de mineral con la descarga recibida de correa alimentación acopio 2120-CV-0002. El acopio de mineral permite alimentar a la planta de manera continua, hasta 10 horas después de cualquier parada del sistema de chancado (capacidad viva de 2.900 t). | G25: Rotura de chute | H25: No afectación a producción, Parada de chancador de mandíbula, Costos por reparación de chute | I25: 1 | J25: 1 | K25: =+IF(I25="","",IF((I25-J25)>0,"Si","No")) -> No | L25: Ninguna | M25: 0.41666667 | N25: 1 | O25: 70 | P25: 10 | Q25: =+IF(M25="","",(IF(((M25*24)-P25)<0,0,(M25*24)-P25)*N25)) -> 0 | R25: =+(IF(((M25*24)-P25)<0,0,((M25*24)-P25)*'Estimación de pérdidas'!$F$72))*N25 -> 0 | S25: No | T25: 3-Posible | U25: =+IF(R25="","",IF(R25<50001,1,IF(R25<200001,2,IF(R25<500001,3,IF(R25<1000001,4,5))))) -> 1 | V25: 1 | Z25: =MAX(U25:Y25) -> 1 | AA25: =IF(Z25=1,VLOOKUP(T25,$AH$3:$AI$7,2,FALSE),IF(Z25=2,VLOOKUP(T25,$AH$8:$AI$12,2, FALSE),IF(Z25=3,VLOOKUP(T25,$AH$13:$AI$17,2,FALSE),IF(Z25=4,VLOOKUP(T25,$AH$18:$AI$22,2,FALSE),IF(Z25=5,VLOOKUP(T25,$AH$23:$AI$27,2,FALSE),""))))) -> Bajo | AB25: =IF(T25="1-Raro",IF(Z25=1,1,IF(Z25=2,3,IF(Z25=3,6,IF(Z25=4,10,15)))),IF(T25="2-Improbable",IF(Z25=1,2,IF(Z25=2,5,IF(Z25=3,9,IF(Z25=4,14,19)))),IF(T25="3-Posible",IF(Z25=1,4,IF(Z25=2,8,IF(Z25=3,13,IF(Z25=4,18,21)))),IF(T25="4-Probable",IF(Z25=1,7,IF(Z25=2,12,IF(Z25=3,17,IF(Z25=4,22,23)))),IF(T25="5-Casi Seguro",IF(Z25=1,11,IF(Z25=2,16,IF(Z25=3,20,IF(Z25=4,24,25))))))))) -> 4 | AC25: =((VLOOKUP(T25,$AH$3:$AJ$7,3,FALSE)*SQRT(U25^2+V25^2+W25^2+X25^2+Y25^2))/(5*SQRT((5)*5^2))) -> 0.075894664 | AH25: 3-Posible | AI25: Alto
A26: 2100 Chancado Primario & Acopio Mineral Mina | B26: 2120 Alimentación acopio de gruesos | C26: Sistema bajada polea cabeza (tecle + motor eléctrico) | D26: 2120ME0004 | E26: Sistema bajada polea cabeza | F26: Bajar polea cabeza de correa para mantención | G26: Falla de cableado / cadena | H26: No afectación a operaciones, Cambiar el tecle | I26: 1 | J26: 1 | K26: =+IF(I26="","",IF((I26-J26)>0,"Si","No")) -> No | L26: Ninguna | M26: 0.25 | N26: 0 | P26: 0 | Q26: =+IF(M26="","",(IF(((M26*24)-P26)<0,0,(M26*24)-P26)*N26)) -> 0 | R26: =+(IF(((M26*24)-P26)<0,0,((M26*24)-P26)*'Estimación de pérdidas'!$F$72))*N26 -> 0 | S26: No | T26: 3-Posible | U26: =+IF(R26="","",IF(R26<50001,1,IF(R26<200001,2,IF(R26<500001,3,IF(R26<1000001,4,5))))) -> 1 | V26: 1 | Z26: =MAX(U26:Y26) -> 1 | AA26: =IF(Z26=1,VLOOKUP(T26,$AH$3:$AI$7,2,FALSE),IF(Z26=2,VLOOKUP(T26,$AH$8:$AI$12,2, FALSE),IF(Z26=3,VLOOKUP(T26,$AH$13:$AI$17,2,FALSE),IF(Z26=4,VLOOKUP(T26,$AH$18:$AI$22,2,FALSE),IF(Z26=5,VLOOKUP(T26,$AH$23:$AI$27,2,FALSE),""))))) -> Bajo | AB26: =IF(T26="1-Raro",IF(Z26=1,1,IF(Z26=2,3,IF(Z26=3,6,IF(Z26=4,10,15)))),IF(T26="2-Improbable",IF(Z26=1,2,IF(Z26=2,5,IF(Z26=3,9,IF(Z26=4,14,19)))),IF(T26="3-Posible",IF(Z26=1,4,IF(Z26=2,8,IF(Z26=3,13,IF(Z26=4,18,21)))),IF(T26="4-Probable",IF(Z26=1,7,IF(Z26=2,12,IF(Z26=3,17,IF(Z26=4,22,23)))),IF(T26="5-Casi Seguro",IF(Z26=1,11,IF(Z26=2,16,IF(Z26=3,20,IF(Z26=4,24,25))))))))) -> 4 | AC26: =((VLOOKUP(T26,$AH$3:$AJ$7,3,FALSE)*SQRT(U26^2+V26^2+W26^2+X26^2+Y26^2))/(5*SQRT((5)*5^2))) -> 0.075894664 | AH26: 2-Improbable | AI26: Alto
A27: 2200 Pila acopio de gruesos | B27: 2210 Acopio de gruesos & sistema recuperación | C27: Chute descarga acopio | D27: 2210CH0014 | E27: Chute descarga acopio | F27: Recepcionar material chancado del acopio de mineral y conducir a alimentador placas 2210FE0001 | G27: Rotura de chute | H27: No afectación directa a operación, Parada de feeder 2210FE0001, Costos por reparación de chute | I27: 1 | J27: 1 | K27: =+IF(I27="","",IF((I27-J27)>0,"Si","No")) -> No | L27: Ninguna | M27: 0.41666667 | N27: 0.2 | O27: 91.32 | P27: 1 | Q27: =+IF(M27="","",(IF(((M27*24)-P27)<0,0,(M27*24)-P27)*N27)) -> 1.8 | R27: =+(IF(((M27*24)-P27)<0,0,((M27*24)-P27)*'Estimación de pérdidas'!$F$72))*N27 -> 103820.53 | S27: No | T27: 3-Posible | U27: =+IF(R27="","",IF(R27<50001,1,IF(R27<200001,2,IF(R27<500001,3,IF(R27<1000001,4,5))))) -> 2 | V27: 1 | Z27: =MAX(U27:Y27) -> 2 | AA27: =IF(Z27=1,VLOOKUP(T27,$AH$3:$AI$7,2,FALSE),IF(Z27=2,VLOOKUP(T27,$AH$8:$AI$12,2, FALSE),IF(Z27=3,VLOOKUP(T27,$AH$13:$AI$17,2,FALSE),IF(Z27=4,VLOOKUP(T27,$AH$18:$AI$22,2,FALSE),IF(Z27=5,VLOOKUP(T27,$AH$23:$AI$27,2,FALSE),""))))) -> Moderado | AB27: =IF(T27="1-Raro",IF(Z27=1,1,IF(Z27=2,3,IF(Z27=3,6,IF(Z27=4,10,15)))),IF(T27="2-Improbable",IF(Z27=1,2,IF(Z27=2,5,IF(Z27=3,9,IF(Z27=4,14,19)))),IF(T27="3-Posible",IF(Z27=1,4,IF(Z27=2,8,IF(Z27=3,13,IF(Z27=4,18,21)))),IF(T27="4-Probable",IF(Z27=1,7,IF(Z27=2,12,IF(Z27=3,17,IF(Z27=4,22,23)))),IF(T27="5-Casi Seguro",IF(Z27=1,11,IF(Z27=2,16,IF(Z27=3,20,IF(Z27=4,24,25))))))))) -> 8 | AC27: =((VLOOKUP(T27,$AH$3:$AJ$7,3,FALSE)*SQRT(U27^2+V27^2+W27^2+X27^2+Y27^2))/(5*SQRT((5)*5^2))) -> 0.12 | AH27: 1-Raro | AI27: Moderado
A28: 2200 Pila acopio de gruesos | B28: 2210 Acopio de gruesos & sistema recuperación | C28: Chute descarga acopio | D28: 2210CH0015 | E28: Chute descarga acopio | F28: Recepcionar material chancado del acopio de mineral y conducir a alimentador placas 2210FE0002 | G28: Rotura de chute | H28: No afectación directa a operación, Parada de feeder 2210FE0002, Costos por reparación de chute | I28: 1 | J28: 1 | K28: =+IF(I28="","",IF((I28-J28)>0,"Si","No")) -> No | L28: Ninguna | M28: 0.41666667 | N28: 0.2 | O28: 91.32 | P28: 1 | Q28: =+IF(M28="","",(IF(((M28*24)-P28)<0,0,(M28*24)-P28)*N28)) -> 1.8 | R28: =+(IF(((M28*24)-P28)<0,0,((M28*24)-P28)*'Estimación de pérdidas'!$F$72))*N28 -> 103820.53 | S28: No | T28: 3-Posible | U28: =+IF(R28="","",IF(R28<50001,1,IF(R28<200001,2,IF(R28<500001,3,IF(R28<1000001,4,5))))) -> 2 | V28: 1 | Z28: =MAX(U28:Y28) -> 2 | AA28: =IF(Z28=1,VLOOKUP(T28,$AH$3:$AI$7,2,FALSE),IF(Z28=2,VLOOKUP(T28,$AH$8:$AI$12,2, FALSE),IF(Z28=3,VLOOKUP(T28,$AH$13:$AI$17,2,FALSE),IF(Z28=4,VLOOKUP(T28,$AH$18:$AI$22,2,FALSE),IF(Z28=5,VLOOKUP(T28,$AH$23:$AI$27,2,FALSE),""))))) -> Moderado | AB28: =IF(T28="1-Raro",IF(Z28=1,1,IF(Z28=2,3,IF(Z28=3,6,IF(Z28=4,10,15)))),IF(T28="2-Improbable",IF(Z28=1,2,IF(Z28=2,5,IF(Z28=3,9,IF(Z28=4,14,19)))),IF(T28="3-Posible",IF(Z28=1,4,IF(Z28=2,8,IF(Z28=3,13,IF(Z28=4,18,21)))),IF(T28="4-Probable",IF(Z28=1,7,IF(Z28=2,12,IF(Z28=3,17,IF(Z28=4,22,23)))),IF(T28="5-Casi Seguro",IF(Z28=1,11,IF(Z28=2,16,IF(Z28=3,20,IF(Z28=4,24,25))))))))) -> 8 | AC28: =((VLOOKUP(T28,$AH$3:$AJ$7,3,FALSE)*SQRT(U28^2+V28^2+W28^2+X28^2+Y28^2))/(5*SQRT((5)*5^2))) -> 0.12
A29: 2200 Pila acopio de gruesos | B29: 2210 Acopio de gruesos & sistema recuperación | C29: Sistema de lanzas | D29: 2210ME0001 | E29: Sistema de lanzas | F29: Bloquear o habilitar la descarga de chute 2210CH0069 y alimentar apron feeder 2210FE0001 | G29: Falla en cilindro hidráulico | H29: Afectación no directa a operaciones (20%), Detención de feeder 2210FE0001, Costos por cambio de cilindro hidráulico | I29: 1 | J29: 1 | K29: =+IF(I29="","",IF((I29-J29)>0,"Si","No")) -> No | L29: Ninguna | M29: 0.25 | N29: 0.5 | O29: 91.32 | P29: 1 | Q29: =+IF(M29="","",(IF(((M29*24)-P29)<0,0,(M29*24)-P29)*N29)) -> 2.5 | R29: =+(IF(((M29*24)-P29)<0,0,((M29*24)-P29)*'Estimación de pérdidas'!$F$72))*N29 -> 144195.19 | S29: No | T29: 3-Posible | U29: =+IF(R29="","",IF(R29<50001,1,IF(R29<200001,2,IF(R29<500001,3,IF(R29<1000001,4,5))))) -> 2 | V29: 1 | Z29: =MAX(U29:Y29) -> 2 | AA29: =IF(Z29=1,VLOOKUP(T29,$AH$3:$AI$7,2,FALSE),IF(Z29=2,VLOOKUP(T29,$AH$8:$AI$12,2, FALSE),IF(Z29=3,VLOOKUP(T29,$AH$13:$AI$17,2,FALSE),IF(Z29=4,VLOOKUP(T29,$AH$18:$AI$22,2,FALSE),IF(Z29=5,VLOOKUP(T29,$AH$23:$AI$27,2,FALSE),""))))) -> Moderado | AB29: =IF(T29="1-Raro",IF(Z29=1,1,IF(Z29=2,3,IF(Z29=3,6,IF(Z29=4,10,15)))),IF(T29="2-Improbable",IF(Z29=1,2,IF(Z29=2,5,IF(Z29=3,9,IF(Z29=4,14,19)))),IF(T29="3-Posible",IF(Z29=1,4,IF(Z29=2,8,IF(Z29=3,13,IF(Z29=4,18,21)))),IF(T29="4-Probable",IF(Z29=1,7,IF(Z29=2,12,IF(Z29=3,17,IF(Z29=4,22,23)))),IF(T29="5-Casi Seguro",IF(Z29=1,11,IF(Z29=2,16,IF(Z29=3,20,IF(Z29=4,24,25))))))))) -> 8 | AC29: =((VLOOKUP(T29,$AH$3:$AJ$7,3,FALSE)*SQRT(U29^2+V29^2+W29^2+X29^2+Y29^2))/(5*SQRT((5)*5^2))) -> 0.12
A30: 2200 Pila acopio de gruesos | B30: 2210 Acopio de gruesos & sistema recuperación | C30: Sistema de lanzas | D30: 2210ME0002 | E30: Sistema de lanzas | F30: Bloquear o habilitar la descarga de chute 2210CH0070 y alimentar apron feeder 2210FE0002 | G30: Falla en cilindro hidráulico | H30: Afectación no directa a operaciones (20%), Detención de feeder 2210FE0001, Costos por cambio de cilindro hidráulico | I30: 1 | J30: 1 | K30: =+IF(I30="","",IF((I30-J30)>0,"Si","No")) -> No | L30: Ninguna | M30: 0.25 | N30: 0.5 | O30: 91.32 | P30: 1 | Q30: =+IF(M30="","",(IF(((M30*24)-P30)<0,0,(M30*24)-P30)*N30)) -> 2.5 | R30: =+(IF(((M30*24)-P30)<0,0,((M30*24)-P30)*'Estimación de pérdidas'!$F$72))*N30 -> 144195.19 | S30: No | T30: 3-Posible | U30: =+IF(R30="","",IF(R30<50001,1,IF(R30<200001,2,IF(R30<500001,3,IF(R30<1000001,4,5))))) -> 2 | V30: 1 | Z30: =MAX(U30:Y30) -> 2 | AA30: =IF(Z30=1,VLOOKUP(T30,$AH$3:$AI$7,2,FALSE),IF(Z30=2,VLOOKUP(T30,$AH$8:$AI$12,2, FALSE),IF(Z30=3,VLOOKUP(T30,$AH$13:$AI$17,2,FALSE),IF(Z30=4,VLOOKUP(T30,$AH$18:$AI$22,2,FALSE),IF(Z30=5,VLOOKUP(T30,$AH$23:$AI$27,2,FALSE),""))))) -> Moderado | AB30: =IF(T30="1-Raro",IF(Z30=1,1,IF(Z30=2,3,IF(Z30=3,6,IF(Z30=4,10,15)))),IF(T30="2-Improbable",IF(Z30=1,2,IF(Z30=2,5,IF(Z30=3,9,IF(Z30=4,14,19)))),IF(T30="3-Posible",IF(Z30=1,4,IF(Z30=2,8,IF(Z30=3,13,IF(Z30=4,18,21)))),IF(T30="4-Probable",IF(Z30=1,7,IF(Z30=2,12,IF(Z30=3,17,IF(Z30=4,22,23)))),IF(T30="5-Casi Seguro",IF(Z30=1,11,IF(Z30=2,16,IF(Z30=3,20,IF(Z30=4,24,25))))))))) -> 8 | AC30: =((VLOOKUP(T30,$AH$3:$AJ$7,3,FALSE)*SQRT(U30^2+V30^2+W30^2+X30^2+Y30^2))/(5*SQRT((5)*5^2))) -> 0.12
A31: 2200 Pila acopio de gruesos | B31: 2210 Acopio de gruesos & sistema recuperación | C31: Chute descarga alimentador | D31: 2210CH0018 | E31: Chute descarga alimentador | F31: Recepcionar mineral chancado de alimentador 2210-FE-0001 y descargar a 2210-CV-0003 correa alimentación Molino SAG | G31: Rotura de chute | H31: No afectación directa a operación, Parada de feeder 2210FE0001 que alimenta correa de Molino SAG, Costos por reparación de chute | I31: 1 | J31: 1 | K31: =+IF(I31="","",IF((I31-J31)>0,"Si","No")) -> No | L31: Ninguna | M31: 0.41666667 | N31: 0.2 | O31: 91.32 | P31: 1 | Q31: =+IF(M31="","",(IF(((M31*24)-P31)<0,0,(M31*24)-P31)*N31)) -> 1.8 | R31: =+(IF(((M31*24)-P31)<0,0,((M31*24)-P31)*'Estimación de pérdidas'!$F$72))*N31 -> 103820.53 | S31: No | T31: 3-Posible | U31: =+IF(R31="","",IF(R31<50001,1,IF(R31<200001,2,IF(R31<500001,3,IF(R31<1000001,4,5))))) -> 2 | V31: 1 | Z31: =MAX(U31:Y31) -> 2 | AA31: =IF(Z31=1,VLOOKUP(T31,$AH$3:$AI$7,2,FALSE),IF(Z31=2,VLOOKUP(T31,$AH$8:$AI$12,2, FALSE),IF(Z31=3,VLOOKUP(T31,$AH$13:$AI$17,2,FALSE),IF(Z31=4,VLOOKUP(T31,$AH$18:$AI$22,2,FALSE),IF(Z31=5,VLOOKUP(T31,$AH$23:$AI$27,2,FALSE),""))))) -> Moderado | AB31: =IF(T31="1-Raro",IF(Z31=1,1,IF(Z31=2,3,IF(Z31=3,6,IF(Z31=4,10,15)))),IF(T31="2-Improbable",IF(Z31=1,2,IF(Z31=2,5,IF(Z31=3,9,IF(Z31=4,14,19)))),IF(T31="3-Posible",IF(Z31=1,4,IF(Z31=2,8,IF(Z31=3,13,IF(Z31=4,18,21)))),IF(T31="4-Probable",IF(Z31=1,7,IF(Z31=2,12,IF(Z31=3,17,IF(Z31=4,22,23)))),IF(T31="5-Casi Seguro",IF(Z31=1,11,IF(Z31=2,16,IF(Z31=3,20,IF(Z31=4,24,25))))))))) -> 8 | AC31: =((VLOOKUP(T31,$AH$3:$AJ$7,3,FALSE)*SQRT(U31^2+V31^2+W31^2+X31^2+Y31^2))/(5*SQRT((5)*5^2))) -> 0.12
